Workbook

Sheet Times
B3: Tribo | C3: Squad
B4: Aprendizagem Digital | C4: Aprendizagem
B5: Aprendizagem Digital | C5: Avaliação
B6: Aprendizagem Digital | C6: Comunicação
B7: Aprendizagem Digital | C7: Interação
B8: Aprendizagem Digital | C8: Plataforma
B9: Aprendizagem Digital | C9: Secretaria e Financeiro
B10: Atendimento & Serviço | C10: Athenas Atendimento
B11: Atendimento & Serviço | C11: kbots
B12: Atendimento & Serviço | C12: Papa-léguas
B13: Atendimento & Serviço | C13: Route66
B14: Financeiro | C14: Eagles
... B49: Total Geral | C49: Total Geral

Sheet Apoio
A1: Sprint 2026 | B1: Dias Úteis | C1: Inicio | D1: Fim | F1: PIs 2026 | H1: Sprint 2025 | I1: Dias Úteis | J1: Inicio | K1: Fim | M1: PIs 2025 | O1: Sprint 2024 | P1: Dias Úteis | Q1: Inicio | R1: Fim | T1: PIs 2024 | V1: Pis 2023
A2: SP 26.1.1 | B2: 7 | C2: 46041 | D2: =C2+11 -> 46052 | F2: PI 1/26 | H2: SP 25.1.1 | I2: 7 | J2: 45677 | K2: =J2+11 -> 45688 | M2: PI 1/25 | O2: SP 24.1.1 | P2: 8 | Q2: 45313 | R2: 45324 | T2: PI 1/24 | V2: PI 1/23
A3: SP 26.1.2 | B3: 8 | C3: =D2+3 -> 46055 | D3: =C3+11 -> 46066 | F3: PI 2/26 | H3: SP 25.1.2 | I3: 8 | J3: =K2+3 -> 45691 | K3: =J3+11 -> 45702 | M3: PI 2/25 | O3: SP 24.1.2 | P3: 6 | Q3: 45327 | R3: 45338 | T3: PI 2/24 | V3: PI 2/23
A4: SP 26.1.3 | B4: 6 | C4: =D3+3 -> 46069 | D4: =C4+11 -> 46080 | F4: PI 3/26 | H4: SP 25.1.3 | I4: 8 | J4: =K3+3 -> 45705 | K4: =J4+11 -> 45716 | M4: PI 3/25 | O4: SP 24.1.3 | P4: 8 | Q4: 45341 | R4: 45352 | T4: PI 3/24 | V4: PI 3/23
A5: SP 26.1.4 | B5: 8 | C5: =D4+3 -> 46083 | D5: =C5+11 -> 46094 | F5: PI 4/26 | H5: SP 25.1.4 | I5: 6 | J5: =K4+3 -> 45719 | K5: =J5+11 -> 45730 | M5: PI 4/25 | O5: SP 24.1.4 | P5: 8 | Q5: 45355 | R5: 45366 | T5: PI 4/24 | V5: PI 4/23
A6: SP 26.1.5 | B6: 8 | C6: =D5+3 -> 46097 | D6: =C6+11 -> 46108 | H6: SP 25.1.5 | I6: 8 | J6: =K5+3 -> 45733 | K6: =J6+11 -> 45744 | O6: SP 24.1.5 | P6: 7 | Q6: 45369 | R6: 45380
A7: SP 26.1.6 | B7: 2 | C7: =D6+3 -> 46111 | D7: =C7+11 -> 46122 | H7: SP 25.1.6 | I7: 3 | J7: =K6+3 -> 45747 | K7: =J7+11 -> 45758 | O7: SP 24.1.6 | P7: 3 | Q7: 45383 | R7: 45394
A8: SP 26.2.1 | B8: 5 | C8: =D7+3 -> 46125 | D8: =C8+11 -> 46136 | H8: SP 25.2.1 | I8: 6 | J8: =K7+3 -> 45761 | K8: =J8+11 -> 45772 | O8: SP 24.2.1 | P8: 8 | Q8: 45397 | R8: 45408
A9: SP 26.2.2 | B9: 7 | C9: =D8+3 -> 46139 | D9: =C9+11 -> 46150 | H9: SP 25.2.2 | I9: 7 | J9: =K8+3 -> 45775 | K9: =J9+11 -> 45786 | O9: SP 24.2.2 | P9: 7 | Q9: 45411 | R9: 45422
A10: SP 26.2.3 | B10: 8 | C10: =D9+3 -> 46153 | D10: =C10+11 -> 46164 | H10: SP 25.2.3 | I10: 8 | J10: =K9+3 -> 45789 | K10: =J10+11 -> 45800 | O10: SP 24.2.3 | P10: 8 | Q10: 45425 | R10: 45436
A11: SP 26.2.4 | B11: 7 | C11: =D10+3 -> 46167 | D11: =C11+11 -> 46178 | H11: SP 25.2.4 | I11: 8 | J11: =K10+3 -> 45803 | K11: =J11+11 -> 45814 | O11: SP 24.2.4 | P11: 7 | Q11: 45439 | R11: 45450
A12: SP 26.2.5 | B12: 8 | C12: =D11+3 -> 46181 | D12: =C12+11 -> 46192 | H12: SP 25.2.5 | I12: 7 | J12: =K11+3 -> 45817 | K12: =J12+11 -> 45828 | O12: SP 24.2.5 | P12: 4 | Q12: 45453 | R12: 45464
A13: SP 26.2.6 | B13: 3 | C13: =D12+3 -> 46195 | D13: =C13+11 -> 46206 | H13: SP 25.2.6 | I13: 3 | J13: =K12+3 -> 45831 | K13: =J13+11 -> 45842 | O13: SP 24.3.1 | P13: 12 | Q13: 45467 | R13: 45485
A14: SP 26.3.1 | B14: 7 | C14: =D13+3 -> 46209 | D14: =C14+11 -> 46220 | H14: SP 25.3.1 | I14: 7 | J14: =K13+3 -> 45845 | K14: =J14+11 -> 45856 | O14: SP 24.3.2 | P14: 8 | Q14: 45488 | R14: 45499
A15: SP 26.3.2 | B15: 8 | C15: =D14+3 -> 46223 | D15: =C15+11 -> 46234 | H15: SP 25.3.2 | I15: 8 | J15: =K14+3 -> 45859 | K15: =J15+11 -> 45870 | O15: SP 24.3.3 | P15: 8 | Q15: 45502 | R15: 45513
A16: SP 26.3.3 | B16: 8 | C16: =D15+3 -> 46237 | D16: =C16+11 -> 46248 | H16: SP 25.3.3 | I16: 8 | J16: =K15+3 -> 45873 | K16: =J16+11 -> 45884 | O16: SP 24.3.4 | P16: 8 | Q16: 45516 | R16: 45527
A17: SP 26.3.4 | B17: 8 | C17: =D16+3 -> 46251 | D17: =C17+11 -> 46262 | H17: SP 25.3.4 | I17: 13 | J17: =K16+3 -> 45887 | K17: =J17+18 -> 45905 | O17: SP 24.3.5 | P17: 8 | Q17: 45530 | R17: 45541
A18: SP 26.3.5 | B18: 7 | C18: =D17+3 -> 46265 | D18: =C18+11 -> 46276 | H18: SP 25.3.5 | I18: 3 | J18: =K17+3 -> 45908 | K18: =J18+11 -> 45919 | O18: SP 24.3.6 | P18: 3 | Q18: 45544 | R18: 45555
A19: SP 26.3.6 | B19: 3 | C19: =D18+3 -> 46279 | D19: =C19+11 -> 46290 | H19: SP 25.4.1 | I19: 13 | J19: =K18+3 -> 45922 | K19: =J19+18 -> 45940 | O19: SP 24.4.1 | P19: 13 | Q19: 45558 | R19: 45576
A20: SP 26.4.1 | B20: 8 | C20: =D19+3 -> 46293 | D20: =C20+11 -> 46304 | H20: SP 25.4.2 | I20: 8 | J20: =K19+3 -> 45943 | K20: =J20+11 -> 45954 | O20: SP 24.4.2 | P20: 8 | Q20: 45579 | R20: 45590
A21: SP 26.4.2 | B21: 7 | C21: =D20+3 -> 46307 | D21: =C21+11 -> 46318 | H21: SP 25.4.3 | I21: 8 | J21: =K20+3 -> 45957 | K21: =J21+11 -> 45968 | O21: SP 24.4.3 | P21: 8 | Q21: 45593 | R21: 45604
A22: SP 26.4.3 | B22: 7 | C22: =D21+3 -> 46321 | D22: =C22+11 -> 46332 | H22: SP 25.4.4 | I22: 7 | J22: =K21+3 -> 45971 | K22: =J22+11 -> 45982 | O22: SP 24.4.4 | P22: 6 | Q22: 45607 | R22: 45618
A23: SP 26.4.4 | B23: 7 | C23: =D22+3 -> 46335 | D23: =C23+11 -> 46346 | H23: SP 25.4.5 | I23: 8 | J23: =K22+3 -> 45985 | K23: =J23+11 -> 45996 | O23: SP 24.4.5 | P23: 8 | Q23: 45621 | R23: 45632
A24: SP 26.4.5 | B24: 8 | C24: =D23+3 -> 46349 | D24: =C24+11 -> 46360 | H24: SP 25.4.6 | I24: 8 | J24: =K23+3 -> 45999 | K24: =J24+11 -> 46010 | O24: SP 24.4.6 | P24: 8 | Q24: 45635 | R24: 45646
A25: SP 26.4.6 | B25: 8 | C25: =D24+3 -> 46363 | D25: =C25+11 -> 46374
O46: S

Sheet 2023
A1: Jornada | B1: Time | C1: PI | D1: Sprint | E1: Velocity
A2: Financeira | B2: House of Money | C2: PI 1/23 | D2: SP 23.1.1 | E2: 35
A3: Financeira | B3: House of Money | C3: PI 1/23 | D3: SP 23.1.2 | E3: 35
A4: Financeira | B4: House of Money | C4: PI 1/23 | D4: SP 23.1.3 | E4: 25
A5: Financeira | B5: House of Money | C5: PI 1/23 | D5: SP 23.1.4 | E5: 35
A6: Financeira | B6: House of Money | C6: PI 1/23 | D6: SP 23.1.5 | E6: 18
A7: Financeira | B7: House of Money | C7: PI 2/23 | D7: SP 23.2.1 | E7: 27
A8: Financeira | B8: House of Money | C8: PI 2/23 | D8: SP 23.2.2 | E8: 33
A9: Financeira | B9: House of Money | C9: PI 2/23 | D9: SP 23.2.3 | E9: 25
A10: Financeira | B10: House of Money | C10: PI 2/23 | D10: SP 23.2.4 | E10: 30
A11: Financeira | B11: House of Money | C11: PI 2/23 | D11: SP 23.2.5 | E11: 29
A12: Financeira | B12: House of Money | C12: PI 2/23 | D12: SP 23.2.6 | E12: 37
A13: Financeira | B13: House of Money | C13: PI 2/23 | D13: SP 23.2.7 | E13: 0
... A434: Academico | B434: Aprendizagem | C434: PI 2/23 | D434: SP 23.2.4 | E434: 42
A435: Academico | B435: Aprendizagem | C435: PI 2/23 | D435: SP 23.2.5 | E435: 9 | G435: 36
A436: Academico | B436: Aprendizagem | C436: PI 2/23 | D436: SP 23.2.6 | E436: 63
A437: Academico | B437: Aprendizagem | C437: PI 2/23 | D437: SP 23.2.7 | E437: 40
A438: Academico | B438: Aprendizagem | C438: PI 3/23 | D438: SP 23.3.1 | E438: 41
A439: Academico | B439: Aprendizagem | C439: PI 3/23 | D439: SP 23.3.2 | E439: 32
A440: Academico | B440: Aprendizagem | C440: PI 3/23 | D440: SP 23.3.3 | E440: 31
A441: Academico | B441: Aprendizagem | C441: PI 3/23 | D441: SP 23.3.4 | E441: 36
A442: Academico | B442: Aprendizagem | C442: PI 3/23 | D442: SP 23.3.5 | E442: 16
A443: Academico | B443: Aprendizagem | C443: PI 4/23 | D443: SP 23.4.1 | E443: 35
A444: Academico | B444: Aprendizagem | C444: PI 4/23 | D444: SP 23.4.2 | E444: 31
A445: Academico | B445: Aprendizagem | C445: PI 4/23 | D445: SP 23.4.3 | E445: 31
A446: Academico | B446: Aprendizagem | C446: PI 4/23 | D446: SP 23.4.4 | E446: 31
A447: Academico | B447: Aprendizagem | C447: PI 4/23 | D447: SP 23.4.5 | E447: 31
... A464: Academico | B464: Avaliação | C464: PI 3/23 | D464: SP 23.3.4 | E464: 32
A465: Academico | B465: Avaliação | C465: PI 3/23 | D465: SP 23.3.5 | E465: 13 | G465: 27
A466: Academico | B466: Avaliação | C466: PI 4/23 | D466: SP 23.4.1 | E466: 24
A467: Academico | B467: Avaliação | C467: PI 4/23 | D467: SP 23.4.2 | E467: 24
A468: Academico | B468: Avaliação | C468: PI 4/23 | D468: SP 23.4.3 | E468: 24
A469: Academico | B469: Avaliação | C469: PI 4/23 | D469: SP 23.4.4 | E469: 24
A470: Academico | B470: Avaliação | C470: PI 4/23 | D470: SP 23.4.5 | E470: 24
A471: Academico | B471: Avaliação | C471: PI 4/23 | D471: SP 23.4.6 | E471: 5
A472: Academico | B472: Docencia | C472: PI 1/23 | D472: SP 23.1.1 | E472: 0
A473: Academico | B473: Docencia | C473: PI 1/23 | D473: SP 23.1.2 | E473: 0
A474: Academico | B474: Docencia | C474: PI 1/23 | D474: SP 23.1.3 | E474: 0
A475: Academico | B475: Docencia | C475: PI 1/23 | D475: SP 23.1.4 | E475: 0
A476: Academico | B476: Docencia | C476: PI 1/23 | D476: SP 23.1.5 | E476: 0
...

Sheet 2024
A1: Jornada | B1: Time | C1: Qtde de Devs | D1: Produtividade (H/P) | E1: Horas Produtivas por dia e por Dev | F1: PI | G1: Sprint | H1: Dias Úteis da Sprint | I1: Velocity
A2: Administrativo | B2: kbots | C2: 5 | D2: 7.5 | E2: 7.5 | F2: PI 1/24 | G2: SP 24.1.1 | H2: =IF(G2>0,VLOOKUP(G2,Apoio!$O$2:$P$24,2,0),"") -> 8 | I2: =IF(D2>0,(((H2*E2)*C2)/D2),"") -> 40
A3: Administrativo | B3: kbots | C3: 5 | D3: 7.5 | E3: 7.5 | F3: PI 1/24 | G3: SP 24.1.2 | H3: =IF(G3>0,VLOOKUP(G3,Apoio!$O$2:$P$24,2,0),"") -> 6 | I3: =IF(D3>0,(((H3*E3)*C3)/D3),"") -> 30
A4: Administrativo | B4: kbots | C4: 5 | D4: 7.5 | E4: 7.5 | F4: PI 1/24 | G4: SP 24.1.3 | H4: =IF(G4>0,VLOOKUP(G4,Apoio!$O$2:$P$24,2,0),"") -> 8 | I4: =IF(D4>0,(((H4*E4)*C4)/D4),"") -> 40
A5: Administrativo | B5: kbots | C5: 5 | D5: 7.5 | E5: 7.5 | F5: PI 1/24 | G5: SP 24.1.4 | H5: =IF(G5>0,VLOOKUP(G5,Apoio!$O$2:$P$24,2,0),"") -> 8 | I5: =IF(D5>0,(((H5*E5)*C5)/D5),"") -> 40
A6: Administrativo | B6: kbots | C6: 5 | D6: 7.5 | E6: 7.5 | F6: PI 1/24 | G6: SP 24.1.5 | H6: =IF(G6>0,VLOOKUP(G6,Apoio!$O$2:$P$24,2,0),"") -> 7 | I6: =IF(D6>0,(((H6*E6)*C6)/D6),"") -> 35
A7: Administrativo | B7: kbots | C7: 5 | D7: 7.5 | E7: 7.5 | F7: PI 1/24 | G7: SP 24.1.6 | H7: =IF(G7>0,VLOOKUP(G7,Apoio!$O$2:$P$24,2,0),"") -> 3 | I7: =IF(D7>0,(((H7*E7)*C7)/D7),"") -> 15
A8: Administrativo | B8: kbots | C8: 4 | D8: 6.4 | E8: 7.5 | F8: PI 2/24 | G8: SP 24.2.1 | H8: =IF(G8>0,VLOOKUP(G8,Apoio!$O$2:$P$24,2,0),"") -> 8 | I8: =IF(D8>0,(((H8*E8)*C8)/D8),"") -> 37.5
A9: Administrativo | B9: kbots | C9: 4 | D9: 6.4 | E9: 7.5 | F9: PI 2/24 | G9: SP 24.2.2 | H9: =IF(G9>0,VLOOKUP(G9,Apoio!$O$2:$P$24,2,0),"") -> 7 | I9: =IF(D9>0,(((H9*E9)*C9)/D9),"") -> 32.8125
A10: Administrativo | B10: kbots | C10: 4 | D10: 6.4 | E10: 7.5 | F10: PI 2/24 | G10: SP 24.2.3 | H10: =IF(G10>0,VLOOKUP(G10,Apoio!$O$2:$P$24,2,0),"") -> 8 | I10: =IF(D10>0,(((H10*E10)*C10)/D10),"") -> 37.5
A11: Administrativo | B11: kbots | C11: 4 | D11: 6.4 | E11: 7.5 | F11: PI 2/24 | G11: SP 24.2.4 | H11: =IF(G11>0,VLOOKUP(G11,Apoio!$O$2:$P$24,2,0),"") -> 7 | I11: =IF(D11>0,(((H11*E11)*C11)/D11),"") -> 32.8125
A12: Administrativo | B12: kbots | C12: 4 | D12: 6.4 | E12: 7.5 | F12: PI 2/24 | G12: SP 24.2.5 | H12: =IF(G12>0,VLOOKUP(G12,Apoio!$O$2:$P$24,2,0),"") -> 4 | I12: =IF(D12>0,(((H12*E12)*C12)/D12),"") -> 18.75
A13: Administrativo | B13: kbots | C13: 3 | D13: 5.8 | E13: 7.5 | F13: PI 3/24 | G13: SP 24.3.1 | H13: =IF(G13>0,VLOOKUP(G13,Apoio!$O$2:$P$24,2,0),"") -> 12 | I13: =IF(D13>0,(((H13*E13)*C13)/D13),"") -> 46.551724
... A151: Administrativo | B151: ThreadPool | C151: 5 | D151: 6.7 | E151: 7.5 | F151: PI 4/24 | G151: SP 24.4.6 | H151: =IF(G151>0,VLOOKUP(G151,Apoio!$O$2:$P$24,2,0),"") -> 8 | I151: =IF(D151>0,(((H151*E151)*C151)/D151),"") -> 44.776119
A152: Aprendizagem Digital | B152: Aprendizagem | C152: 7 | D152: 11 | E152: 7.5 | F152: PI 1/24 | G152: SP 24.1.1 | H152: 7 | I152: =IF(D152>0,(((H152*E152)*C152)/D152),"") -> 33.409091
A153: Aprendizagem Digital | B153: Aprendizagem | C153: 7.5 | D153: 11 | E153: 7.5 | F153: PI 1/24 | G153: SP 24.1.2 | H153: 6 | I153: =IF(D153>0,(((H153*E153)*C153)/D153),"") -> 30.681818
A154: Aprendizagem Digital | B154: Aprendizagem | C154: 8 | D154: 11 | E154: 7.5 | F154: PI 1/24 | G154: SP 24.1.3 | H154: 8 | I154: =IF(D154>0,(((H154*E154)*C154)/D154),"") -> 43.636364
A155: Aprendizagem Digital | B155: Aprendizagem | C155: 7 | D155: 11 | E155: 7.5 | F155: PI 1/24 | G155: SP 24.1.4 | H155: 8 | I155: =IF(D155>0,(((H155*E155)*C155)/D155),"") -> 38.181818
A156: Aprendizagem Digital | B156: Aprendizagem | C156: 7 | D156: 11 | E156: 7.5 | F156: PI 1/24 | G156: SP 24.1.5 | H156: 7 | I156: =IF(D156>0,(((H156*E156)*C156)/D156),"") -> 33.409091
A157: Aprendizagem Digital | B157: Aprendizagem | C157: 7 | D157: 11 | E157: 7.5 | F157: PI 1/24 | G157: SP 24.1.6 | H157: 3 | I157: =IF(D157>0,(((H157*E157)*C157)/D157),"") -> 14.318182
A158: Aprendizagem Digital | B158: Aprendizagem | C158: 6 | D158: 7 | E158: 7.5 | F158: PI 2/24 | G158: SP 24.2.1 | H158: 8 | I158: =IF(D158>0,(((H158*E158)*C158)/D158),"") -> 51.428571
A159: Aprendizagem Digital | B159: Aprendizagem | C159: 6 | D159: 7 | E159: 7.5 | F159: PI 2/24 | G159: SP 24.2.1 | H159: 8 | I159: =IF(D159>0,(((H159*E159)*C159)/D159),"") -> 51.428571
A160: Aprendizagem Digital | B160: Aprendizagem | C160: 6 | D160: 7 | E160: 7.5 | F160: PI 2/24 | G160: SP 24.2.2 | H160: 7 | I160: =IF(D160>0,(((H160*E160)*C160)/D160),"") -> 45
A161: Aprendizagem Digital | B161: Aprendizagem | C161: 6 | D161: 7 | E161: 7.5 | F161: PI 2/24 | G161: SP 24.2.2 | H161: 7 | I161: =IF(D161>0,(((H161*E161)*C161)/D161),"") -> 45
A162: Aprendizagem Digital | B162: Aprendizagem | C162: 6 | D162: 7 | E162: 7.5 | F162: PI 2/24 | G162: SP 24.2.3 | H162: 8 | I162: =IF(D162>0,(((H162*E162)*C162)/D162),"") -> 51.428571
A163: Aprendizagem Digital | B163: Aprendizagem | C163: 6 | D163: 7 | E163: 7.5 | F163: PI 2/24 | G163: SP 24.2.3 | H163: 8 | I163: =IF(D163>0,(((H163*E163)*C163)/D163),"") -> 51.428571
... A167: Aprendizagem Digital | B167: Aprendizagem | C167: 6 | D167: 7 | E167: 7.5 | F167: PI 2/24 | G167: SP 24.2.5 | H167: 4 | I167: =IF(D167>0,(((H167*E167)*C167)/D167),"") -> 25.714286
A168: Aprendizagem Digital | B168: Aprendizagem | C168: 4.7 | D168: 5.6 | E168: 7.5 | F168: PI 3/24 | G168: SP 24.3.1 | H168: =IF(G168>0,VLOOKUP(G168,Apoio!$O$2:$P$24,2,0),"") -> 12 | I168: =IF(D168>0,(((H168*E168)*C168)/D168),"") -> 75.535714
A169: Aprendizagem Digital | B169: Aprendizagem | C169: 4 | D169: 5.6 | E169: 7.5 | F169: PI 3/24 | G169: SP 24.3.2 | H169: =IF(G169>0,VLOOKUP(G169,Apoio!$O$2:$P$24,2,0),"") -> 8 | I169: =IF(D169>0,(((H169*E169)*C169)/D169),"") -> 42.857143
A170: Aprendizagem Digital | B170: Aprendizagem | C170: 5 | D170: 5.6 | E170: 7.5 | F170: PI 3/24 | G170: SP 24.3.3 | H170: =IF(G170>0,VLOOKUP(G170,Apoio!$O$2:$P$24,2,0),"") -> 8 | I170: =IF(D170>0,(((H170*E170)*C170)/D170),"") -> 53.571429
A171: Aprendizagem Digital | B171: Aprendizagem | C171: 4 | D171: 5.6 | E171: 7.5 | F171: PI 3/24 | G171: SP 24.3.4 | H171: =IF(G171>0,VLOOKUP(G171,Apoio!$O$2:$P$24,2,0),"") -> 8 | I171: =IF(D171>0,(((H171*E171)*C171)/D171),"") -> 42.857143
A172: Aprendizagem Digital | B172: Aprendizagem | C172: 5 | D172: 5.6 | E172: 7.5 | F172: PI 3/24 | G172: SP 24.3.5 | H172: =IF(G172>0,VLOOKUP(G172,Apoio!$O$2:$P$24,2,0),"") -> 8 | I172: =IF(D172>0,(((H172*E172)*C172)/D172),"") -> 53.571429
A173: Aprendizagem Digital | B173: Aprendizagem | C173: 4 | D173: 5.6 | E173: 7.5 | F173: PI 3/24 | G173: SP 24.3.6 | H173: =IF(G173>0,VLOOKUP(G173,Apoio!$O$2:$P$24,2,0),"") -> 3 | I173: =IF(D173>0,(((H173*E173)*C173)/D173),"") -> 16.071429
A174: Aprendizagem Digital | B174: Aprendizagem | C174: 4.2 | D174: 5.5 | E174: 7.5 | F174: PI 4/24 | G174: SP 24.4.1 | H174: 12 | I174: =IF(D174>0,(((H174*E174)*C174)/D174),"") -> 68.727273
A175: Aprendizagem Digital | B175: Aprendizagem | C175: 4.5 | D175: 5.5 | E175: 7.5 | F175: PI 4/24 | G175: SP 24.4.2 | H175: 8 | I175: =IF(D175>0,(((H175*E175)*C175)/D175),"") -> 49.090909
A176: Aprendizagem Digital | B176: Aprendizagem | C176: 4 | D176: 5.5 | E176: 7.5 | F176: PI 4/24 | G176: SP 24.4.3 | H176: 8 | I176: =IF(D176>0,(((H176*E176)*C176)/D176),"") -> 43.636364
A177: Aprendizagem Digital | B177: Aprendizagem | C177: 5 | D177: 5.5 | E177: 7.5 | F177: PI 4/24 | G177: SP 24.4.4 | H177: 6 | I177: =IF(D177>0,(((H177*E177)*C177)/D177),"") -> 40.909091
A178: Aprendizagem Digital | B178: Aprendizagem | C178: 5 | D178: 5.5 | E178: 7.5 | F178: PI 4/24 | G178: SP 24.4.5 | H178: 8 | I178: =IF(D178>0,(((H178*E178)*C178)/D178),"") -> 54.545455
A179: Aprendizagem Digital | B179: Aprendizagem | C179: 5 | D179: 5.5 | E179: 7.5 | F179: PI 4/24 | G179: SP 24.4.6 | H179: 8 | I179: =IF(D179>0,(((H179*E179)*C179)/D179),"") -> 54.545455
A180: Aprendizagem Digital | B180: Avaliação | C180: 7 | D180: 14 | E180: 7.5 | F180: PI 1/24 | G180: SP 24.1.1 | H180: 7 | I180: =IF(D180>0,(((H180*E180)*C180)/D180),"") -> 26.25
...

Sheet 2025
A1: Jornada | B1: Time | C1: Qtde de Devs | D1: Produtividade (H/P) | E1: Horas Produtivas por dia e por Dev | F1: PI | G1: Sprint | H1: Dias Úteis da Sprint | I1: Velocity | J1: Sustentação | K1: Status Time
A2: Administrativo | B2: kbots | C2: 4 | D2: 5.3 | E2: 7 | F2: PI 1/25 | G2: SP 25.1.1 | H2: =IF(G2>0,VLOOKUP(G2,Apoio!$H$2:$I$24,2,0),"") -> 7 | I2: =IF(D2>0,(((H2*E2)*C2)/D2),"") -> 36.981132
A3: Administrativo | B3: kbots | C3: 4 | D3: 5.3 | E3: 7 | F3: PI 1/25 | G3: SP 25.1.2 | H3: =IF(G3>0,VLOOKUP(G3,Apoio!$H$2:$I$24,2,0),"") -> 8 | I3: =IF(D3>0,(((H3*E3)*C3)/D3),"") -> 42.264151
A4: Administrativo | B4: kbots | C4: 4 | D4: 5.3 | E4: 7 | F4: PI 1/25 | G4: SP 25.1.3 | H4: =IF(G4>0,VLOOKUP(G4,Apoio!$H$2:$I$24,2,0),"") -> 8 | I4: =IF(D4>0,(((H4*E4)*C4)/D4),"") -> 42.264151
A5: Administrativo | B5: kbots | C5: 4 | D5: 5.3 | E5: 7 | F5: PI 1/25 | G5: SP 25.1.4 | H5: =IF(G5>0,VLOOKUP(G5,Apoio!$H$2:$I$24,2,0),"") -> 6 | I5: =IF(D5>0,(((H5*E5)*C5)/D5),"") -> 31.698113
A6: Administrativo | B6: kbots | C6: 4 | D6: 5.3 | E6: 7 | F6: PI 1/25 | G6: SP 25.1.5 | H6: =IF(G6>0,VLOOKUP(G6,Apoio!$H$2:$I$24,2,0),"") -> 8 | I6: =IF(D6>0,(((H6*E6)*C6)/D6),"") -> 42.264151
A7: Administrativo | B7: kbots | C7: 4 | D7: 5.3 | E7: 7 | F7: PI 1/25 | G7: SP 25.1.6 | H7: =IF(G7>0,VLOOKUP(G7,Apoio!$H$2:$I$24,2,0),"") -> 3 | I7: =IF(D7>0,(((H7*E7)*C7)/D7),"") -> 15.849057
A8: Administrativo | B8: kbots | C8: 4 | D8: 8 | E8: 7 | F8: PI 2/25 | G8: SP 25.2.1 | H8: =IF(G8>0,VLOOKUP(G8,Apoio!$H$2:$I$24,2,0),"") -> 6 | I8: =IF(D8>0,(((H8*E8)*C8)/D8),"") -> 21
A9: Administrativo | B9: kbots | C9: 4 | D9: 8 | E9: 7 | F9: PI 2/25 | G9: SP 25.2.2 | H9: =IF(G9>0,VLOOKUP(G9,Apoio!$H$2:$I$24,2,0),"") -> 7 | I9: =IF(D9>0,(((H9*E9)*C9)/D9),"") -> 24.5
A10: Administrativo | B10: kbots | C10: 4 | D10: 8 | E10: 7 | F10: PI 2/25 | G10: SP 25.2.3 | H10: =IF(G10>0,VLOOKUP(G10,Apoio!$H$2:$I$24,2,0),"") -> 8 | I10: =IF(D10>0,(((H10*E10)*C10)/D10),"") -> 28
A11: Administrativo | B11: kbots | C11: 4 | D11: 8 | E11: 7 | F11: PI 2/25 | G11: SP 25.2.4 | H11: =IF(G11>0,VLOOKUP(G11,Apoio!$H$2:$I$24,2,0),"") -> 8 | I11: =IF(D11>0,(((H11*E11)*C11)/D11),"") -> 28
A12: Administrativo | B12: kbots | C12: 4 | D12: 8 | E12: 7 | F12: PI 2/25 | G12: SP 25.2.5 | H12: =IF(G12>0,VLOOKUP(G12,Apoio!$H$2:$I$24,2,0),"") -> 7 | I12: =IF(D12>0,(((H12*E12)*C12)/D12),"") -> 24.5
A13: Administrativo | B13: kbots | C13: 4 | D13: 8 | E13: 7 | F13: PI 2/25 | G13: SP 25.2.6 | H13: =IF(G13>0,VLOOKUP(G13,Apoio!$H$2:$I$24,2,0),"") -> 3 | I13: =IF(D13>0,(((H13*E13)*C13)/D13),"") -> 10.5
... A89: Atendimento & Serviço | B89: Athenas Atendimento | C89: 6 | D89: 5 | E89: 7 | F89: PI 3/25 | G89: SP 25.3.1 | H89: =IF(G89>0,VLOOKUP(G89,Apoio!$H$2:$I$24,2,0),"") -> 7 | I89: =IF(D89>0,(((H89*E89)*C89)/D89),"") -> 58.8
A90: Atendimento & Serviço | B90: Athenas Atendimento | C90: 6 | D90: 5 | E90: 7 | F90: PI 3/25 | G90: SP 25.3.2 | H90: =IF(G90>0,VLOOKUP(G90,Apoio!$H$2:$I$24,2,0),"") -> 8 | I90: =IF(D90>0,(((H90*E90)*C90)/D90),"") -> 67.2 | O90: =625-116 -> 509
A91: Atendimento & Serviço | B91: Athenas Atendimento | C91: 6 | D91: 5 | E91: 7 | F91: PI 3/25 | G91: SP 25.3.3 | H91: =IF(G91>0,VLOOKUP(G91,Apoio!$H$2:$I$24,2,0),"") -> 8 | I91: =IF(D91>0,(((H91*E91)*C91)/D91),"") -> 67.2
A92: Atendimento & Serviço | B92: Athenas Atendimento | C92: 6 | D92: 5 | E92: 7 | F92: PI 3/25 | G92: SP 25.3.4 | H92: =IF(G92>0,VLOOKUP(G92,Apoio!$H$2:$I$24,2,0),"") -> 13 | I92: =IF(D92>0,(((H92*E92)*C92)/D92),"") -> 109.2
A93: Atendimento & Serviço | B93: Athenas Atendimento | C93: 6 | D93: 5 | E93: 7 | F93: PI 3/25 | G93: SP 25.3.5 | H93: =IF(G93>0,VLOOKUP(G93,Apoio!$H$2:$I$24,2,0),"") -> 3 | I93: =IF(D93>0,(((H93*E93)*C93)/D93),"") -> 25.2
A94: Atendimento & Serviço | B94: Athenas Atendimento | C94: 6 | D94: 6 | E94: 6 | F94: PI 4/25 | G94: SP 25.4.1 | H94: =IF(G94>0,VLOOKUP(G94,Apoio!$H$2:$I$24,2,0),"") -> 13 | I94: =IF(D94>0,(((H94*E94)*C94)/D94),"") -> 78
A95: Atendimento & Serviço | B95: Athenas Atendimento | C95: 6 | D95: 6 | E95: 6 | F95: PI 4/25 | G95: SP 25.4.2 | H95: =IF(G95>0,VLOOKUP(G95,Apoio!$H$2:$I$24,2,0),"") -> 8 | I95: =IF(D95>0,(((H95*E95)*C95)/D95),"") -> 48
A96: Atendimento & Serviço | B96: Athenas Atendimento | C96: 6 | D96: 6 | E96: 6 | F96: PI 4/25 | G96: SP 25.4.3 | H96: =IF(G96>0,VLOOKUP(G96,Apoio!$H$2:$I$24,2,0),"") -> 8 | I96: =IF(D96>0,(((H96*E96)*C96)/D96),"") -> 48
A97: Atendimento & Serviço | B97: Athenas Atendimento | C97: 6 | D97: 6 | E97: 6 | F97: PI 4/25 | G97: SP 25.4.4 | H97: =IF(G97>0,VLOOKUP(G97,Apoio!$H$2:$I$24,2,0),"") -> 7 | I97: =IF(D97>0,(((H97*E97)*C97)/D97),"") -> 42
A98: Atendimento & Serviço | B98: Athenas Atendimento | C98: 6 | D98: 6 | E98: 6 | F98: PI 4/25 | G98: SP 25.4.5 | H98: =IF(G98>0,VLOOKUP(G98,Apoio!$H$2:$I$24,2,0),"") -> 8 | I98: =IF(D98>0,(((H98*E98)*C98)/D98),"") -> 48
A99: Atendimento & Serviço | B99: Athenas Atendimento | C99: 6 | D99: 6 | E99: 6 | F99: PI 4/25 | G99: SP 25.4.6 | H99: =IF(G99>0,VLOOKUP(G99,Apoio!$H$2:$I$24,2,0),"") -> 8 | I99: =IF(D99>0,(((H99*E99)*C99)/D99),"") -> 48
A100: Atendimento & Serviço | B100: Athenas Atendimento | C100: 6 | D100: 6 | E100: 6 | F100: PI 4/25 | G100: SP 25.4.6 | H100: =IF(G100>0,VLOOKUP(G100,Apoio!$H$2:$I$24,2,0),"") -> 8 | I100: =IF(D100>0,(((H100*E100)*C100)/D100),"") -> 48
A101: Administrativo | B101: Athenas Sec. Enturmação | C101: 6 | D101: 7 | E101: 7 | F101: PI 1/25 | G101: SP 25.1.1 | H101: =IF(G101>0,VLOOKUP(G101,Apoio!$H$2:$I$24,2,0),"") -> 7 | I101: =IF(D101>0,(((H101*E101)*C101)/D101),"") -> 42
A102: Administrativo | B102: Athenas Sec. Enturmação | C102: 6 | D102: 7 | E102: 7 | F102: PI 1/25 | G102: SP 25.1.2 | H102: =IF(G102>0,VLOOKUP(G102,Apoio!$H$2:$I$24,2,0),"") -> 8 | I102: =IF(D102>0,(((H102*E102)*C102)/D102),"") -> 48
... A114: Secretaria & Gestor de Unidades | B114: Athenas Sec. Enturmação | C114: 6 | D114: 4.4 | E114: 7 | F114: PI 3/25 | G114: SP 25.3.2 | H114: =IF(G114>0,VLOOKUP(G114,Apoio!$H$2:$I$24,2,0),"") -> 8 | I114: =IF(D114>0,(((H114*E114)*C114)/D114),"") -> 76.363636
A115: Secretaria & Gestor de Unidades | B115: Athenas Sec. Enturmação | C115: 6 | D115: 4.4 | E115: 7 | F115: PI 3/25 | G115: SP 25.3.3 | H115: =IF(G115>0,VLOOKUP(G115,Apoio!$H$2:$I$24,2,0),"") -> 8 | I115: =IF(D115>0,(((H115*E115)*C115)/D115),"") -> 76.363636 | L115: -1 dev | M115: -2 dev (a partir da 4)
A116: Secretaria & Gestor de Unidades | B116: Athenas Sec. Enturmação | C116: 6 | D116: 4.4 | E116: 7 | F116: PI 3/25 | G116: SP 25.3.4 | H116: =IF(G116>0,VLOOKUP(G116,Apoio!$H$2:$I$24,2,0),"") -> 13 | I116: =IF(D116>0,(((H116*E116)*C116)/D116),"") -> 124.09091
A117: Secretaria & Gestor de Unidades | B117: Athenas Sec. Enturmação | C117: 6 | D117: 4.4 | E117: 7 | F117: PI 3/25 | G117: SP 25.3.5 | H117: =IF(G117>0,VLOOKUP(G117,Apoio!$H$2:$I$24,2,0),"") -> 3 | I117: =IF(D117>0,(((H117*E117)*C117)/D117),"") -> 28.636364
A118: Secretaria & Gestor de Unidades | B118: Athenas Sec. Enturmação | C118: 4 | D118: 4.4 | E118: 6 | F118: PI 4/25 | G118: SP 25.4.1 | H118: =IF(G118>0,VLOOKUP(G118,Apoio!$H$2:$I$24,2,0),"") -> 13 | I118: =IF(D118>0,(((H118*E118)*C118)/D118),"") -> 70.909091
A119: Secretaria & Gestor de Unidades | B119: Athenas Sec. Enturmação | C119: 4 | D119: 4.4 | E119: 6 | F119: PI 4/25 | G119: SP 25.4.2 | H119: =IF(G119>0,VLOOKUP(G119,Apoio!$H$2:$I$24,2,0),"") -> 8 | I119: =IF(D119>0,(((H119*E119)*C119)/D119),"") -> 43.636364
A120: Secretaria & Gestor de Unidades | B120: Athenas Sec. Enturmação | C120: 4 | D120: 4.4 | E120: 6 | F120: PI 4/25 | G120: SP 25.4.3 | H120: =IF(G120>0,VLOOKUP(G120,Apoio!$H$2:$I$24,2,0),"") -> 8 | I120: =IF(D120>0,(((H120*E120)*C120)/D120),"") -> 43.636364
A121: Secretaria & Gestor de Unidades | B121: Athenas Sec. Enturmação | C121: 4 | D121: 4.4 | E121: 6 | F121: PI 4/25 | G121: SP 25.4.4 | H121: =IF(G121>0,VLOOKUP(G121,Apoio!$H$2:$I$24,2,0),"") -> 7 | I121: =IF(D121>0,(((H121*E121)*C121)/D121),"") -> 38.181818
A122: Secretaria & Gestor de Unidades | B122: Athenas Sec. Enturmação | C122: 4 | D122: 4.4 | E122: 6 | F122: PI 4/25 | G122: SP 25.4.5 | H122: =IF(G122>0,VLOOKUP(G122,Apoio!$H$2:$I$24,2,0),"") -> 8 | I122: =IF(D122>0,(((H122*E122)*C122)/D122),"") -> 43.636364
A123: Secretaria & Gestor de Unidades | B123: Athenas Sec. Enturmação | C123: 4 | D123: 4.4 | E123: 6 | F123: PI 4/25 | G123: SP 25.4.6 | H123: =IF(G123>0,VLOOKUP(G123,Apoio!$H$2:$I$24,2,0),"") -> 8 | I123: =IF(D123>0,(((H123*E123)*C123)/D123),"") -> 43.636364
A124: Administrativo | B124: Athenas Sec. Gestão Acad. | C124: 6 | D124: 7 | E124: 7 | F124: PI 1/25 | G124: SP 25.1.1 | H124: =IF(G124>0,VLOOKUP(G124,Apoio!$H$2:$I$24,2,0),"") -> 7 | I124: =IF(D124>0,(((H124*E124)*C124)/D124),"") -> 42
A125: Administrativo | B125: Athenas Sec. Gestão Acad. | C125: 6 | D125: 7 | E125: 7 | F125: PI 1/25 | G125: SP 25.1.2 | H125: =IF(G125>0,VLOOKUP(G125,Apoio!$H$2:$I$24,2,0),"") -> 8 | I125: =IF(D125>0,(((H125*E125)*C125)/D125),"") -> 48
A126: Administrativo | B126: Athenas Sec. Gestão Acad. | C126: 6 | D126: 7 | E126: 7 | F126: PI 1/25 | G126: SP 25.1.3 | H126: =IF(G126>0,VLOOKUP(G126,Apoio!$H$2:$I$24,2,0),"") -> 8 | I126: =IF(D126>0,(((H126*E126)*C126)/D126),"") -> 48
...

Sheet Dinamica 2025
A1: PI | B1: PI 4/25
A2: Status Time | B2: (Vários itens)
A4: Rótulos de Linha | B4: Soma de Velocity | C4: Soma de Sustentação
A5: Aprendizagem Digital | B5: 2765.9716 | C5: 677.94601
A6: Financeiro | B6: 855.24389 | C6: 264.22934
A7: Ingresso | B7: 1787.8505
A8: Jornada Acadêmica | B8: 1047.5238 | C8: 276.58132
A9: Pos Graduação | B9: 636.55172
A10: Saber | B10: 1255.55 | C10: 168.0525
A11: Inteligencia Artificial | B11: 744.375
A12: Voomp | B12: 1205.868
A13: Atendimento & Serviço | B13: 1337.0047
A14: Secretaria & Gestor de Unidades | B14: 1683.0649
A15: Total Geral | B15: 13319.004 | C15: 1386.8092

Sheet Dinamica 2026
A1: PI | B1: (Tudo)
A2: Sprint | B2: SP 26.1.1
A4: Rótulos de Linha | B4: Média de Produtividade (H/P)
A5: Aprendizagem Digital | B5: 5.2833333
A6: Atendimento & Serviço | B6: 5.75
A7: Ingresso | B7: 6.5666667
A8: Inteligencia Artificial | B8: 6.9666667
A9: Jornada Acadêmica | B9: 5.375
A10: Pos Graduação | B10: 6.9
A11: Saber | B11: 5.2666667
A12: Secretaria & Gestor de Unidades | B12: 6.28
A13: Voomp | B13: 6.6285714
A14: Total Geral | B14: 6.0975

Sheet 2026_Produtividade
A1: Jornada | B1: Time | C1: Qtde de Devs | D1: Produtividade (H/P) | E1: Horas Produtivas por dia e por Dev | F1: PI | G1: Sprint | H1: Dias Úteis da Sprint | I1: Velocity | J1: Média dos Pts de Sustentação da PI passada | K1: Capacity | L1: Custo da Sprint: Pontos x Valor (R$ 2647,87) | M1: Status Time | N1: Observações: redução da capacidade por ausência
A2: Atendimento e Serviço | B2: kbots | C2: 4 | D2: 5 | E2: 7 | F2: PI 1/26 | G2: SP 26.1.1 | H2: =IF(G2>0,VLOOKUP(G2,Apoio!$A$2:$B$25,2,0),"") -> 7 | I2: =IF(D2>0,(((H2*E2)*C2)/D2),"") -> 39.2 | M2: Gestão Jéssica Molero
A3: Atendimento e Serviço | B3: kbots | C3: 4 | D3: 5 | E3: 7 | F3: PI 1/26 | G3: SP 26.1.2 | H3: =IF(G3>0,VLOOKUP(G3,Apoio!$A$2:$B$25,2,0),"") -> 8 | I3: =IF(D3>0,(((H3*E3)*C3)/D3),"") -> 44.8 | M3: Gestão Jéssica Molero
A4: Atendimento e Serviço | B4: kbots | C4: 4 | D4: 5 | E4: 7 | F4: PI 1/26 | G4: SP 26.1.3 | H4: =IF(G4>0,VLOOKUP(G4,Apoio!$A$2:$B$25,2,0),"") -> 6 | I4: =IF(D4>0,(((H4*E4)*C4)/D4),"") -> 33.6 | M4: Gestão Jéssica Molero
A5: Atendimento e Serviço | B5: kbots | C5: 4 | D5: 5 | E5: 7 | F5: PI 1/26 | G5: SP 26.1.4 | H5: =IF(G5>0,VLOOKUP(G5,Apoio!$A$2:$B$25,2,0),"") -> 8 | I5: =IF(D5>0,(((H5*E5)*C5)/D5),"") -> 44.8 | M5: Gestão Jéssica Molero
A6: Atendimento e Serviço | B6: kbots | C6: 4 | D6: 5 | E6: 7 | F6: PI 1/26 | G6: SP 26.1.5 | H6: =IF(G6>0,VLOOKUP(G6,Apoio!$A$2:$B$25,2,0),"") -> 8 | I6: =IF(D6>0,(((H6*E6)*C6)/D6),"") -> 44.8 | M6: Gestão Jéssica Molero
A7: Atendimento e Serviço | B7: kbots | C7: 4 | D7: 5 | E7: 7 | F7: PI 1/26 | G7: SP 26.1.6 | H7: =IF(G7>0,VLOOKUP(G7,Apoio!$A$2:$B$25,2,0),"") -> 2 | I7: =IF(D7>0,(((H7*E7)*C7)/D7),"") -> 11.2 | M7: Gestão Jéssica Molero
A8: Atendimento e Serviço | B8: kbots | C8: 4 | D8: 5 | E8: 7 | F8: PI 2/26 | G8: SP 26.2.1 | H8: =IF(G8>0,VLOOKUP(G8,Apoio!$A$2:$B$25,2,0),"") -> 5 | I8: =IF(D8>0,(((H8*E8)*C8)/D8),"") -> 28 | M8: Gestão Jéssica Molero
A9: Atendimento e Serviço | B9: kbots | C9: 4 | D9: 5 | E9: 7 | F9: PI 2/26 | G9: SP 26.2.2 | H9: =IF(G9>0,VLOOKUP(G9,Apoio!$A$2:$B$25,2,0),"") -> 7 | I9: =IF(D9>0,(((H9*E9)*C9)/D9),"") -> 39.2 | M9: Gestão Jéssica Molero
A10: Atendimento e Serviço | B10: kbots | C10: 4 | D10: 5 | E10: 7 | F10: PI 2/26 | G10: SP 26.2.3 | H10: =IF(G10>0,VLOOKUP(G10,Apoio!$A$2:$B$25,2,0),"") -> 8 | I10: =IF(D10>0,(((H10*E10)*C10)/D10),"") -> 44.8 | M10: Gestão Jéssica Molero
A11: Atendimento e Serviço | B11: kbots | C11: 4 | D11: 5 | E11: 7 | F11: PI 2/26 | G11: SP 26.2.4 | H11: =IF(G11>0,VLOOKUP(G11,Apoio!$A$2:$B$25,2,0),"") -> 7 | I11: =IF(D11>0,(((H11*E11)*C11)/D11),"") -> 39.2 | M11: Gestão Jéssica Molero
A12: Atendimento e Serviço | B12: kbots | C12: 4 | D12: 5 | E12: 7 | F12: PI 2/26 | G12: SP 26.2.5 | H12: =IF(G12>0,VLOOKUP(G12,Apoio!$A$2:$B$25,2,0),"") -> 8 | I12: =IF(D12>0,(((H12*E12)*C12)/D12),"") -> 44.8 | M12: Gestão Jéssica Molero
A13: Atendimento e Serviço | B13: kbots | C13: 4 | D13: 5 | E13: 7 | F13: PI 2/26 | G13: SP 26.2.6 | H13: =IF(G13>0,VLOOKUP(G13,Apoio!$A$2:$B$25,2,0),"") -> 3 | I13: =IF(D13>0,(((H13*E13)*C13)/D13),"") -> 16.8 | M13: Gestão Jéssica Molero
... A19: Atendimento e Serviço | B19: kbots | C19: 4 | D19: 5 | E19: 7 | F19: PI 3/26 | G19: SP 26.3.6 | H19: =IF(G19>0,VLOOKUP(G19,Apoio!$A$2:$B$25,2,0),"") -> 3 | I19: =IF(D19>0,(((H19*E19)*C19)/D19),"") -> 16.8 | M19: Gestão Jéssica Molero
A20: Atendimento e Serviço | B20: kbots | C20: 4 | D20: 5 | E20: 7 | F20: PI 4/26 | G20: SP 26.4.1 | H20: =IF(G20>0,VLOOKUP(G20,Apoio!$A$2:$B$25,2,0),"") -> 8 | I20: =IF(D20>0,(((H20*E20)*C20)/D20),"") -> 44.8 | J20: 8 | K20: =I20-J20 -> 36.8 | M20: Gestão Jéssica Molero
A21: Atendimento e Serviço | B21: kbots | C21: 4 | D21: 5 | E21: 7 | F21: PI 4/26 | G21: SP 26.4.2 | H21: =IF(G21>0,VLOOKUP(G21,Apoio!$A$2:$B$25,2,0),"") -> 7 | I21: =IF(D21>0,(((H21*E21)*C21)/D21),"") -> 39.2 | J21: 8 | K21: =I21-J21 -> 31.2 | M21: Gestão Jéssica Molero
A22: Atendimento e Serviço | B22: kbots | C22: 4 | D22: 5 | E22: 7 | F22: PI 4/26 | G22: SP 26.4.3 | H22: =IF(G22>0,VLOOKUP(G22,Apoio!$A$2:$B$25,2,0),"") -> 7 | I22: =IF(D22>0,(((H22*E22)*C22)/D22),"") -> 39.2 | J22: 8 | K22: =I22-J22 -> 31.2 | M22: Gestão Jéssica Molero
A23: Atendimento e Serviço | B23: kbots | C23: 4 | D23: 5 | E23: 7 | F23: PI 4/26 | G23: SP 26.4.4 | H23: =IF(G23>0,VLOOKUP(G23,Apoio!$A$2:$B$25,2,0),"") -> 7 | I23: =IF(D23>0,(((H23*E23)*C23)/D23),"") -> 39.2 | J23: 8 | K23: =I23-J23 -> 31.2 | M23: Gestão Jéssica Molero
A24: Atendimento e Serviço | B24: kbots | C24: 4 | D24: 5 | E24: 7 | F24: PI 4/26 | G24: SP 26.4.5 | H24: =IF(G24>0,VLOOKUP(G24,Apoio!$A$2:$B$25,2,0),"") -> 8 | I24: =IF(D24>0,(((H24*E24)*C24)/D24),"") -> 44.8 | J24: 8 | K24: =I24-J24 -> 36.8 | M24: Gestão Jéssica Molero
A25: Atendimento e Serviço | B25: kbots | C25: 4 | D25: 5 | E25: 7 | F25: PI 4/26 | G25: SP 26.4.6 | H25: =IF(G25>0,VLOOKUP(G25,Apoio!$A$2:$B$25,2,0),"") -> 8 | I25: =IF(D25>0,(((H25*E25)*C25)/D25),"") -> 44.8 | J25: 8 | K25: =I25-J25 -> 36.8 | M25: Gestão Jéssica Molero
A26: Atendimento e Serviço | B26: Papa-léguas | C26: 5 | D26: 6 | E26: 7 | F26: PI 1/26 | G26: SP 26.1.1 | H26: =IF(G26>0,VLOOKUP(G26,Apoio!$A$2:$B$25,2,0),"") -> 7 | I26: =IF(D26>0,(((H26*E26)*C26)/D26),"") -> 40.833333 | M26: Gestão Jéssica Molero
A27: Atendimento e Serviço | B27: Papa-léguas | C27: 5 | D27: 6 | E27: 7 | F27: PI 1/26 | G27: SP 26.1.2 | H27: =IF(G27>0,VLOOKUP(G27,Apoio!$A$2:$B$25,2,0),"") -> 8 | I27: =IF(D27>0,(((H27*E27)*C27)/D27),"") -> 46.666667 | M27: Gestão Jéssica Molero
A28: Atendimento e Serviço | B28: Papa-léguas | C28: 5 | D28: 6 | E28: 7 | F28: PI 1/26 | G28: SP 26.1.3 | H28: =IF(G28>0,VLOOKUP(G28,Apoio!$A$2:$B$25,2,0),"") -> 6 | I28: =IF(D28>0,(((H28*E28)*C28)/D28),"") -> 35 | M28: Gestão Jéssica Molero
A29: Atendimento e Serviço | B29: Papa-léguas | C29: 5 | D29: 6 | E29: 7 | F29: PI 1/26 | G29: SP 26.1.4 | H29: =IF(G29>0,VLOOKUP(G29,Apoio!$A$2:$B$25,2,0),"") -> 8 | I29: =IF(D29>0,(((H29*E29)*C29)/D29),"") -> 46.666667 | M29: Gestão Jéssica Molero
A30: Atendimento e Serviço | B30: Papa-léguas | C30: 5 | D30: 6 | E30: 7 | F30: PI 1/26 | G30: SP 26.1.5 | H30: =IF(G30>0,VLOOKUP(G30,Apoio!$A$2:$B$25,2,0),"") -> 8 | I30: =IF(D30>0,(((H30*E30)*C30)/D30),"") -> 46.666667 | M30: Gestão Jéssica Molero
A31: Atendimento e Serviço | B31: Papa-léguas | C31: 5 | D31: 6 | E31: 7 | F31: PI 1/26 | G31: SP 26.1.6 | H31: =IF(G31>0,VLOOKUP(G31,Apoio!$A$2:$B$25,2,0),"") -> 2 | I31: =IF(D31>0,(((H31*E31)*C31)/D31),"") -> 11.666667 | M31: Gestão Jéssica Molero
A32: Atendimento e Serviço | B32: Papa-léguas | C32: 5 | D32: 6 | E32: 7 | F32: PI 2/26 | G32: SP 26.2.1 | H32: =IF(G32>0,VLOOKUP(G32,Apoio!$A$2:$B$25,2,0),"") -> 5 | I32: =IF(D32>0,(((H32*E32)*C32)/D32),"") -> 29.166667 | M32: Gestão Jéssica Molero
A33: Atendimento e Serviço | B33: Papa-léguas | C33: 5 | D33: 6 | E33: 7 | F33: PI 2/26 | G33: SP 26.2.2 | H33: =IF(G33>0,VLOOKUP(G33,Apoio!$A$2:$B$25,2,0),"") -> 7 | I33: =IF(D33>0,(((H33*E33)*C33)/D33),"") -> 40.833333 | M33: Gestão Jéssica Molero
A34: Atendimento e Serviço | B34: Papa-léguas | C34: 5 | D34: 6 | E34: 7 | F34: PI 2/26 | G34: SP 26.2.3 | H34: =IF(G34>0,VLOOKUP(G34,Apoio!$A$2:$B$25,2,0),"") -> 8 | I34: =IF(D34>0,(((H34*E34)*C34)/D34),"") -> 46.666667 | M34: Gestão Jéssica Molero
A35: Atendimento e Serviço | B35: Papa-léguas | C35: 5 | D35: 6 | E35: 7 | F35: PI 2/26 | G35: SP 26.2.4 | H35: =IF(G35>0,VLOOKUP(G35,Apoio!$A$2:$B$25,2,0),"") -> 7 | I35: =IF(D35>0,(((H35*E35)*C35)/D35),"") -> 40.833333 | M35: Gestão Jéssica Molero
A36: Atendimento e Serviço | B36: Papa-léguas | C36: 5 | D36: 6 | E36: 7 | F36: PI 2/26 | G36: SP 26.2.5 | H36: =IF(G36>0,VLOOKUP(G36,Apoio!$A$2:$B$25,2,0),"") -> 8 | I36: =IF(D36>0,(((H36*E36)*C36)/D36),"") -> 46.666667 | M36: Gestão Jéssica Molero
A37: Atendimento e Serviço | B37: Papa-léguas | C37: 5 | D37: 6 | E37: 7 | F37: PI 2/26 | G37: SP 26.2.6 | H37: =IF(G37>0,VLOOKUP(G37,Apoio!$A$2:$B$25,2,0),"") -> 3 | I37: =IF(D37>0,(((H37*E37)*C37)/D37),"") -> 17.5 | M37: Gestão Jéssica Molero
... A43: Atendimento e Serviço | B43: Papa-léguas | C43: 5 | D43: 6 | E43: 7 | F43: PI 3/26 | G43: SP 26.3.6 | H43: =IF(G43>0,VLOOKUP(G43,Apoio!$A$2:$B$25,2,0),"") -> 3 | I43: =IF(D43>0,(((H43*E43)*C43)/D43),"") -> 17.5 | M43: Gestão Jéssica Molero
A44: Atendimento e Serviço | B44: Papa-léguas | C44: 5 | D44: 6 | E44: 7 | F44: PI 4/26 | G44: SP 26.4.1 | H44: =IF(G44>0,VLOOKUP(G44,Apoio!$A$2:$B$25,2,0),"") -> 8 | I44: =IF(D44>0,(((H44*E44)*C44)/D44),"") -> 46.666667 | J44: 8 | K44: =I44-J44 -> 38.666667 | M44: Gestão Jéssica Molero
A45: Atendimento e Serviço | B45: Papa-léguas | C45: 5 | D45: 6 | E45: 7 | F45: PI 4/26 | G45: SP 26.4.2 | H45: =IF(G45>0,VLOOKUP(G45,Apoio!$A$2:$B$25,2,0),"") -> 7 | I45: =IF(D45>0,(((H45*E45)*C45)/D45),"") -> 40.833333 | J45: 8 | K45: =I45-J45 -> 32.833333 | M45: Gestão Jéssica Molero
A46: Atendimento e Serviço | B46: Papa-léguas | C46: 5 | D46: 6 | E46: 7 | F46: PI 4/26 | G46: SP 26.4.3 | H46: =IF(G46>0,VLOOKUP(G46,Apoio!$A$2:$B$25,2,0),"") -> 7 | I46: =IF(D46>0,(((H46*E46)*C46)/D46),"") -> 40.833333 | J46: 8 | K46: =I46-J46 -> 32.833333 | M46: Gestão Jéssica Molero
A47: Atendimento e Serviço | B47: Papa-léguas | C47: 5 | D47: 6 | E47: 7 | F47: PI 4/26 | G47: SP 26.4.4 | H47: =IF(G47>0,VLOOKUP(G47,Apoio!$A$2:$B$25,2,0),"") -> 7 | I47: =IF(D47>0,(((H47*E47)*C47)/D47),"") -> 40.833333 | J47: 8 | K47: =I47-J47 -> 32.833333 | M47: Gestão Jéssica Molero
A48: Atendimento e Serviço | B48: Papa-léguas | C48: 5 | D48: 6 | E48: 7 | F48: PI 4/26 | G48: SP 26.4.5 | H48: =IF(G48>0,VLOOKUP(G48,Apoio!$A$2:$B$25,2,0),"") -> 8 | I48: =IF(D48>0,(((H48*E48)*C48)/D48),"") -> 46.666667 | J48: 8 | K48: =I48-J48 -> 38.666667 | M48: Gestão Jéssica Molero
A49: Atendimento e Serviço | B49: Papa-léguas | C49: 5 | D49: 6 | E49: 7 | F49: PI 4/26 | G49: SP 26.4.6 | H49: =IF(G49>0,VLOOKUP(G49,Apoio!$A$2:$B$25,2,0),"") -> 8 | I49: =IF(D49>0,(((H49*E49)*C49)/D49),"") -> 46.666667 | J49: 8 | K49: =I49-J49 -> 38.666667 | M49: Gestão Jéssica Molero
A50: Atendimento e Serviço | B50: Route66 | C50: 6 | D50: 6 | E50: 7 | F50: PI 1/26 | G50: SP 26.1.1 | H50: =IF(G50>0,VLOOKUP(G50,Apoio!$A$2:$B$25,2,0),"") -> 7 | I50: =IF(D50>0,(((H50*E50)*C50)/D50),"") -> 49 | M50: Gestão Jéssica Molero
...
