Workbook
Name Tab_Baseline: OFFSET(Baseline!#REF!,0,0,COUNTA(Baseline!$A:$A),COUNTA(Baseline!#REF!))
Name Tab_Debitos_Tecnicos_Backlog: OFFSET('Debitos Tecnicos_Backlog'!$A$1,0,0,COUNTA('Debitos Tecnicos_Backlog'!$A:$A),COUNTA('Debitos Tecnicos_Backlog'!$1:$1))
Name Tab_Debitos_Tecnicos_PI: OFFSET('Debitos Tecnicos_PI'!$A$1,0,0,COUNTA('Debitos Tecnicos_PI'!$A:$A),COUNTA('Debitos Tecnicos_PI'!$1:$1))
Name Tab_Épicos_Jornada: OFFSET('Extração Jira - Épicos Jornada'!$A$1,0,0,COUNTA('Extração Jira - Épicos Jornada'!$A:$A),COUNTA('Extração Jira - Épicos Jornada'!$1:$1))
Name Tab_Extração_Jira_Épicos: OFFSET('Extração Jira - Itens (Épicos)'!$A$1,0,0,COUNTA('Extração Jira - Itens (Épicos)'!$A:$A),COUNTA('Extração Jira - Itens (Épicos)'!$1:$1))
Name Tab_Impedimentos: OFFSET(Impedimento!$K$2,0,0,COUNTA(Impedimento!$K$2:$K$135),COUNTA(Impedimento!$K$16:$BR$16))
Name Tab_Itens_Jira: OFFSET('Extração Jira - Itens'!$A$1,0,0,COUNTA('Extração Jira - Itens'!$A:$A),COUNTA('Extração Jira - Itens'!$1:$1))

Sheet Review
B2: REVIEW
B5: Data | C5: Versão | D5: Alteração
B6: 45961 | C6: 13 | D6: - Inclusão do tempo de bloqueio na extração do Jira e na fórmula do ciclo de desenvolvimento - Inclusão do total de story points faltantes para conclusão dos épicos na aba "Situação dos Épicos"

Sheet Informações
B2: INFORMAÇÕES PARA GERAR OS INDICADORES | F2: Leia com atenção
B4: PREMISSAS
B5: * Não deverá considerar as informações da última sprint para gerar os indicadores; * Épicos compartilhados só deverão ser contabilizados na Jornada que é responsavel pelo épico; * Atenção: Colunas pintadas da AZUL contém fórmulas
B7: 1º PASSO: EXTRAÇÃO DAS INFORMAÇÕES
B8: Nome | C8: Descrição | D8: JQL | E8: Colunas | F8: Onde colar as informações
B9: Baseline | C9: Extração de todos os itens planejado pelos times da Jornada na PI Planning OBS: Essa extração é uma foto, deve ter sido feita logo após a PI Planning | D9: project in (APAP, APAV, APSF, APCO, APPL, APIN, ADPL, ADR6, ADKB, ADTH, ADTP, ADGP, ADSE, ASEC, ATEN, JIEC, JICA, JIBK, JIMF, JIAE, JICE, JICS, JACO, JAMO, JAAM, JFHM, JFSP, JFTR, JFEA, APDO, PGCM, PGEX, PGIA, PGAL, PGIA, PGAL, SAJO, SATT, SADV, "[Voomp] Meios de Pagamento", "[Voomp] Admin", "[Voomp] App", "[Voomp] Play", "[Voomp] Pos") AND issuetype in standardIssueTypes() AND Sprint in ("25.2.1","25.2.2", "25.2.3", "25.2.4", "25.2.5", "25.2.6") ORDER BY project | E9: Tipo de item Resumo Chave Status Resolução Criado Start date Resolvido Versões corrigidas Tipo item pai parent Tempo gasto Σ de Tempo Gasto Story point estimate Story Points Sprint Ponto de compromisso Tipo Categoria do status Alteração de escopo (após a última PIP)? Inicio do fluxo Fim do fluxo Início Homologação Fim Homologação Início Implantação Fim Implantação Ciclo de Ideação Ciclo de Desenvolvimento Ciclo Homologação Ciclo de Implantação Lead Time Costumer Lead Time Tipo Sustentação Projeto | F9: Planilha Baseline
B10: Extração Jira - Itens | C10: Extração atual de todos os itens trabalhado pelos times independente do status até a penultima sprint, ou seja, não trazer as informações da última sprint. | D10: project in (ADKB,ADMD,ADPL,ADR6,ADTH,ADTP) AND issuetype in ("Débito Técnico", Enabler, Story, Spike, Teste, Incidente,"Solicitação de Serviço", bug, Sustentação, Suporte) AND SPRINT in ("24.3.1","24.3.2","24.3.3","24.3.4","24.3.5") ORDER BY cf[10315] DESC Link do filtro: https://cogna.atlassian.net/issues/?filter=16979&atlOrigin=eyJpIjoiMmU4ZjExYTU0YjE4NGU3YThkNTNlNTFhMTQ5OTY2ZDkiLCJwIjoiaiJ9 | E10: 1- Tipo de item 2- Resumo 3- Projeto 4- Chave 5- Status 6- Versões corrigidas 7- Sprint 8- Story Points 9- Story point estimate 10- Σ de Tempo Gasto 11- Tipo 12- Categoria do status 13- Pai 14- Alteração de escopo (após a última PIP)? 15- Resolução 16- Criado 17- Ponto de compromisso 18- Inicio do fluxo 19- Fim do fluxo 20- Início Homologação 21- Fim Homologação 22- Início Implantação 23- Fim Implantação 24- Ciclo de Ideação 25- Ciclo de Desenvolvimento 26- Ciclo Homologação 27- Ciclo de Implantação 28- Lead Time 29- Costumer Lead Time 30 - Tipo Sustentação 31 - Este item sofreu antecipação? 32 - Ambiente 33 - Tempo Total Bloqueado | F10: Planilha Extração Jira - Itens
B12: Débitos Tecnicos_Backlog | C12: Extração dos itens cadastrados com Débito técnico que os times ainda não entregaram e não estão planejados para a PI corrente | D12: project = ADPL and issuetype = "Débito Técnico" and status in (backlog) and (sprint not in("25.2") or Sprint = EMPTY) | E12: Recuperando dados. Aguarde alguns segundos e tente cortar ou copiar novamente. | F12: Planilha Débito Técnico *Abaixo da linha amarela
B13: Débitos Tecnicos_PI | C13: Backlog planejado (PI vigente) - todos os status Encerrados (PI vigente) - aceito, pendente produção, em produção Pendente (PI vigente) - tudo diferente de encerrado e cancelado Cancelados (PI vigente) | D13: project = ADPL and issuetype = "Débito Técnico" and sprint in ("25.2") | E13: 1 - Projeto 2 - Tipo de item 3 - Chave 4 - Status 5 - Versão Corrigida 6 - Sprint 7 - Story Points
B14: Extração Jira - Épicos Jornada | C14: Extração da lista de épicos que a tribo é a dona | D14: category IN (ARTPT, "Tribo - Jornada Acadêmica", "Squad - Jornada Acadêmica") And "Jornada dona do Epico[Group Picker (single group)]" = "[ART] Jornada Acadêmica" And issuetype = Epic And fixVersion ~ "*2/25*" | E14: 1- Tipo de item 2- Resumo 3- Projeto 4- Chave 5- Status 6- Versões corrigidas
B15: Extração Jira - Itens (Épicos) | C15: Extração da lista de itens (da tribo ou não) de todos os épicos que a tribo é dona | D15: issuetype in (standardIssueTypes()) and issuetype not in (Design, "Esforço Preliminar") and parent in (ARTPT-385,ARTPT-393, APDO-577, APDO-2061) ORDER BY parent | E15: 1- Tipo de item 2- Resumo 3- Projeto 4- Chave 5- Status 6- Versões corrigidas 7- Sprint 8- Story Points 9- Story point estimate 10- Σ de Tempo Gasto 11- Tipo 12- Categoria do status 13- Pai 14- Alteração de escopo (após a última PIP)? 15- Resolução 16- Criado 17- Ponto de compromisso 18- Inicio do fluxo 19- Fim do fluxo 20- Início Homologação 21- Fim Homologação 22- Início Implantação 23- Fim Implantação 24- Ciclo de Ideação 25- Ciclo de Desenvolvimento 26- Ciclo Homologação 27- Ciclo de Implantação 28- Lead Time 29- Costumer Lead Time 30 - Tipo Sustentação 31 - Este item sofreu antecipação?
B16: - Após colar os dados extraídos é importante converter para número ondem for necessário e verificar se as formulas estão indo até a última linha
B19: 2º PASSO: GERAR CADA INDICADOR
B20: (1) Clicar sobre a tabela dinâmica com o botão direito e clicar na opção "Atualizar"
B21: (2) Preencher as tabelinhas com os valores apresentados nas tabelas dinâmicas (conforme orientações apresentadas em cada indicador)
B22: (3) Conferir se os valores gerados estão conforme esperado
B23: (4) Copiar gráfico para os slides

Sheet Baseline
A1: Tipo de item | B1: Resumo | C1: Chave | D1: Status | E1: Criado | F1: Start date | G1: Versões corrigidas | H1: parent | I1: Tempo gasto | J1: Σ de Tempo Gasto | K1: Story point estimate | L1: Story Points | M1: Sprint | N1: Checklist Progress | O1: Ponto de compromisso | P1: Tipo | Q1: Categoria do status | R1: Alteração de escopo (após a última PIP)? | S1: Inicio do fluxo | T1: Fim do fluxo | U1: Início Homologação | V1: Fim Homologação | W1: Início Implantação | X1: Fim Implantação | Y1: Ciclo de Ideação | Z1: Ciclo de Desenvolvimento | AA1: Ciclo Homologação | AB1: Ciclo de Implantação | AC1: Lead Time | AD1: Costumer Lead Time | AE1: Tipo Sustentação | AF1: Projeto | AG1: Jornada dona do Epico | AH1: Σ Estimativa de trabalho restante | AI1: Alteração de escopo (após a última PIP)? | AJ1: Responsável | AK1: Tempo bloqueado | AL1: Dias Bloqueados | AM1: Squad Responsável | AN1: OKRs de 2025 | AO1: Tipo Sustentação
A2: Incidente | B2: [INC0796440]Tenho um Erro/Problema com o PTC - Dynamics Athenas - Envio de reatórios | C2: SGGU-6546 | D2: Backlog | G2: [SGGU] PI 3/26 | M2: [SGGU] SP 26.3.1 | AF2: [Jornada Secretaria e Gestor de Unidades] Gestor de Unidades | AG2: Jornada Secretaria e Gestor de Unidades
A3: Incidente | B3: [INC0796379]Tenho um Erro/Problema com o PTC - Dynamics Athenas - Inativação de curso e ofertas | C3: SGGU-6545 | D3: Backlog | G3: [SGGU] PI 3/26 | M3: [SGGU] SP 26.3.1 | AF3: [Jornada Secretaria e Gestor de Unidades] Gestor de Unidades | AG3: Jornada Secretaria e Gestor de Unidades
A4: Incidente | B4: [INC0796118]Tenho um Erro/Problema no Dynamics - Gestão de unidades - Reportar um erro/problema | C4: SGGU-6541 | D4: Em Andamento | G4: [SGGU] PI 3/26 | M4: [SGGU] SP 26.3.1 | AF4: [Jornada Secretaria e Gestor de Unidades] Gestor de Unidades | AG4: Jornada Secretaria e Gestor de Unidades
A5: Incidente | B5: [INC0796099]Tenho um Erro/Problema no Dynamics - Gestão de unidades - Reportar um erro/problema | C5: SGGU-6540 | D5: Aceito | G5: [SGGU] PI 3/26 | M5: [SGGU] SP 26.3.1 | AF5: [Jornada Secretaria e Gestor de Unidades] Gestor de Unidades | AG5: Jornada Secretaria e Gestor de Unidades
A6: Incidente | B6: [INC0756582]Tenho um Erro/Problema no Dynamics - Gestão de unidades - Reportar um erro/problema | C6: SGGU-6539 | D6: Aceito | G6: [SGGU] PI 3/26 | M6: [SGGU] SP 26.2.6;[SGGU] SP 26.3.1 | AF6: [Jornada Secretaria e Gestor de Unidades] Gestor de Unidades | AG6: Jornada Secretaria e Gestor de Unidades
A7: Incidente | B7: [INC0794566]Tenho um Erro/Problema no Dynamics - Gestão de unidades - Reportar um erro/problema | C7: SGGU-6536 | D7: Backlog | G7: [SGGU] PI 3/26 | M7: [SGGU] SP 26.2.6;[SGGU] SP 26.3.1 | AF7: [Jornada Secretaria e Gestor de Unidades] Gestor de Unidades | AG7: Jornada Secretaria e Gestor de Unidades
A8: Incidente | B8: [INC0782154]Tenho um Erro/Problema com o PTC - Dynamics Athenas - Atualização de Dados Cadastrais | C8: SGGU-6535 | D8: Aceito | G8: [SGGU] PI 3/26 | M8: [SGGU] SP 26.2.6;[SGGU] SP 26.3.1 | AF8: [Jornada Secretaria e Gestor de Unidades] Gestor de Unidades | AG8: Jornada Secretaria e Gestor de Unidades
A9: Incidente | B9: [INC0794335]Tenho um Erro/Problema no Dynamics - Gestão de unidades - Reportar um erro/problema | C9: SGGU-6534 | D9: Concluído | G9: [SGGU] PI 3/26 | M9: [SGGU] SP 26.2.6;[SGGU] SP 26.3.1 | AF9: [Jornada Secretaria e Gestor de Unidades] Gestor de Unidades | AG9: Jornada Secretaria e Gestor de Unidades
A10: Incidente | B10: [INC0793763]Tenho um Erro/Problema no Dynamics - Gestão de unidades - Reportar um erro/problema | C10: SGGU-6490 | D10: Concluído | G10: [SGGU] PI 3/26 | M10: [SGGU] SP 26.2.6;[SGGU] SP 26.3.1 | AF10: [Jornada Secretaria e Gestor de Unidades] Gestor de Unidades | AG10: Jornada Secretaria e Gestor de Unidades
A11: Teste | B11: Apoio criação de oferta de Serviço Social para time de estágio | C11: SGGU-6446 | D11: Backlog | G11: [SGGU] PI 3/26 | H11: JAES-650 | K11: 2 | L11: 2 | M11: [SGGU] SP 26.3.3 | AF11: [Jornada Secretaria e Gestor de Unidades] Gestor de Unidades | AG11: Jornada Secretaria e Gestor de Unidades
A12: História | B12: [Curso MEC] Mapear quais tabelas, campos e filtros precisam ter ajuste no layout para apresentar o código vínculo (bk) e código mec (atributo) | C12: SGGU-6444 | D12: Backlog | G12: [SGGU] PI 3/26 | H12: SGGS-11290 | K12: 5 | L12: 5 | M12: [SGGU] SP 26.3.3 | AF12: [Jornada Secretaria e Gestor de Unidades] Gestor de Unidades | AG12: Jornada Secretaria e Gestor de Unidades
A13: História | B13: [Curso MEC] Frontend - Realizar alterações para consumir o Código Vínculo (BK) - Curso SEMI | C13: SGGU-6431 | D13: Backlog | G13: [SGGU] PI 3/26 | H13: SGGS-11290 | K13: 5 | L13: 5 | M13: [SGGU] SP 26.3.5 | AF13: [Jornada Secretaria e Gestor de Unidades] Gestor de Unidades | AG13: Jornada Secretaria e Gestor de Unidades
A14: Enabler | B14: [Curso MEC] Backend - Realizar alterações para consumir o Código Vínculo (BK) - Curso SEMI | C14: SGGU-6430 | D14: Backlog | G14: [SGGU] PI 3/26 | H14: SGGS-11290 | K14: 8 | L14: 8 | M14: [SGGU] SP 26.3.4 | AF14: [Jornada Secretaria e Gestor de Unidades] Gestor de Unidades | AG14: Jornada Secretaria e Gestor de Unidades
A15: Enabler | B15: [Curso MEC] Mapear fluxos e alterações que deverão passar a consumir o novo Código Vínculo (BK) e Código MEC (atributo) | C15: SGGU-6429 | D15: Backlog | G15: [SGGU] PI 3/26 | H15: SGGS-11290 | K15: 5 | L15: 5 | M15: [SGGU] SP 26.3.3 | AF15: [Jornada Secretaria e Gestor de Unidades] Gestor de Unidades | AG15: Jornada Secretaria e Gestor de Unidades
A16: Enabler | B16: [Curso MEC] Backend - Realizar alterações para consumir o Código Vínculo (BK) - Tipo de Produto | C16: SGGU-6428 | D16: Backlog | G16: [SGGU] PI 3/26 | H16: SGGS-11290 | K16: 8 | L16: 8 | M16: [SGGU] SP 26.3.4 | AF16: [Jornada Secretaria e Gestor de Unidades] Gestor de Unidades | AG16: Jornada Secretaria e Gestor de Unidades
A17: Enabler | B17: [Curso MEC] Backend - Realizar alterações para consumir o Código Vínculo (BK) - Curso por tipo de produto | C17: SGGU-6427 | D17: Backlog | G17: [SGGU] PI 3/26 | H17: SGGS-11290 | K17: 8 | L17: 8 | M17: [SGGU] SP 26.3.4 | AF17: [Jornada Secretaria e Gestor de Unidades] Gestor de Unidades | AG17: Jornada Secretaria e Gestor de Unidades
A18: Enabler | B18: [Curso MEC] Backend - Realizar alterações para consumir o Código Vínculo (BK) - Portfólio Padrão | C18: SGGU-6426 | D18: Backlog | G18: [SGGU] PI 3/26 | H18: SGGS-11290 | K18: 8 | L18: 8 | M18: [SGGU] SP 26.3.4 | AF18: [Jornada Secretaria e Gestor de Unidades] Gestor de Unidades | AG18: Jornada Secretaria e Gestor de Unidades
A19: História | B19: [Curso MEC] Frontend - Realizar alterações para consumir o Código Vínculo (BK) - Curso por tipo de produto | C19: SGGU-6425 | D19: Backlog | G19: [SGGU] PI 3/26 | H19: SGGS-11290 | K19: 5 | L19: 5 | M19: [SGGU] SP 26.3.5 | AF19: [Jornada Secretaria e Gestor de Unidades] Gestor de Unidades | AG19: Jornada Secretaria e Gestor de Unidades
A20: História | B20: [Curso MEC] Frontend - Realizar alterações para consumir o Código Vínculo (BK) - Portfólio Padrão | C20: SGGU-6424 | D20: Backlog | G20: [SGGU] PI 3/26 | H20: SGGS-11290 | K20: 5 | L20: 5 | M20: [SGGU] SP 26.3.5 | AF20: [Jornada Secretaria e Gestor de Unidades] Gestor de Unidades | AG20: Jornada Secretaria e Gestor de Unidades
A21: Solicitação de Serviço | B21: [RITM0718223]Solicitação de Serviço ao PTC - Gestão de Unidades - Gestão de Unidades | C21: SGGU-6422 | D21: Backlog | G21: [SGGU] PI 3/26 | M21: [SGGU] SP 26.3.1 | AF21: [Jornada Secretaria e Gestor de Unidades] Gestor de Unidades | AG21: Jornada Secretaria e Gestor de Unidades
A22: Teste | B22: [SGGU-5187] Teste Integrado | C22: SGGU-6420 | D22: Backlog | G22: [SGGU] PI 3/26 | H22: SGGU-5187 | K22: 1 | L22: 1 | M22: [SGGU] SP 26.3.5 | AF22: [Jornada Secretaria e Gestor de Unidades] Gestor de Unidades | AG22: Jornada Secretaria e Gestor de Unidades
A23: Incidente | B23: [INC0792429]Tenho um Erro/Problema com o PTC - Dynamics Athenas - Alocação do tutor a turma | C23: SGGU-6418 | D23: Concluído | G23: [SGGU] PI 3/26 | M23: [SGGU] SP 26.2.6;[SGGU] SP 26.3.1 | AF23: [Jornada Secretaria e Gestor de Unidades] Gestor de Unidades | AG23: Jornada Secretaria e Gestor de Unidades
A24: Incidente | B24: [INC0791299]Tenho um Erro/Problema com o PTC - Dynamics Athenas - Alocação do tutor a turma | C24: SGGU-6413 | D24: Aceito | G24: [SGGU] PI 3/26 | M24: [SGGU] SP 26.2.6;[SGGU] SP 26.3.1 | AF24: [Jornada Secretaria e Gestor de Unidades] Gestor de Unidades | AG24: Jornada Secretaria e Gestor de Unidades
A25: Solicitação de Serviço | B25: [RITM0717458]Solicitação de Serviço ao PTC - Gestão de Unidades - Gestão de Unidades | C25: SGGU-6400 | D25: Concluído | G25: [SGGU] PI 3/26 | M25: [SGGU] SP 26.2.6;[SGGU] SP 26.3.1 | AF25: [Jornada Secretaria e Gestor de Unidades] Gestor de Unidades | AG25: Jornada Secretaria e Gestor de Unidades
A26: Enabler | B26: [GU] [Síncrona Mediada] Analisar o recebimento das informações no tópico | C26: SGGU-6399 | D26: Backlog | G26: [SGGU] PI 3/26 | H26: APAP-10055 | K26: 0 | L26: 2 | M26: [SGGU] SP 26.3.4 | AF26: [Jornada Secretaria e Gestor de Unidades] Gestor de Unidades | AG26: Jornada Secretaria e Gestor de Unidades
A27: Enabler | B27: [GU] [Síncrona Mediada] Teste Regrevisso | C27: SGGU-6392 | D27: Backlog | G27: [SGGU] PI 3/26 | H27: APAP-10055 | K27: 5 | L27: 5 | M27: [SGGU] SP 26.3.6 | AF27: [Jornada Secretaria e Gestor de Unidades] Gestor de Unidades | AG27: Jornada Secretaria e Gestor de Unidades
A28: Enabler | B28: [185] [GU] Validação customização dos plugins | C28: SGGU-6390 | D28: Backlog | G28: [SGGU] PI 3/26 | H28: ARTSG-185 | K28: 1 | L28: 1 | M28: [SGGU] SP 26.3.3 | AF28: [Jornada Secretaria e Gestor de Unidades] Gestor de Unidades | AG28: Jornada Secretaria e Gestor de Unidades
A29: Enabler | B29: [185] [GU] Validação customização dos plugins | C29: SGGU-6389 | D29: Backlog | G29: [SGGU] PI 3/26 | H29: ARTSG-185 | K29: 1 | L29: 1 | M29: [SGGU] SP 26.3.2 | AF29: [Jornada Secretaria e Gestor de Unidades] Gestor de Unidades | AG29: Jornada Secretaria e Gestor de Unidades
A30: Enabler | B30: [GU] [Síncrona Mediada] Consumir tópicos e realizar teste de conectividade | C30: SGGU-6388 | D30: Backlog | G30: [SGGU] PI 3/26 | H30: APAP-10055 | K30: 8 | L30: 8 | M30: [SGGU] SP 26.3.5 | AF30: [Jornada Secretaria e Gestor de Unidades] Gestor de Unidades | AG30: Jornada Secretaria e Gestor de Unidades
A31: Enabler | B31: [185] [GU] Validação customização dos plugins | C31: SGGU-6387 | D31: Backlog | G31: [SGGU] PI 3/26 | H31: ARTSG-185 | K31: 1 | L31: 1 | M31: [SGGU] SP 26.3.1 | AF31: [Jornada Secretaria e Gestor de Unidades] Gestor de Unidades | AG31: Jornada Secretaria e Gestor de Unidades
A32: História | B32: [GU] [Síncrona Mediada] Criar nova tabela/layout/menu | C32: SGGU-6385 | D32: Backlog | G32: [SGGU] PI 3/26 | H32: APAP-10055 | K32: 3 | L32: 3 | M32: [SGGU] SP 26.3.4 | AF32: [Jornada Secretaria e Gestor de Unidades] Gestor de Unidades | AG32: Jornada Secretaria e Gestor de Unidades
A33: Enabler | B33: [SGGU-5202] Parametrização - Atualizar consulta para resgatar a Aula da tabela correta | C33: SGGU-6381 | D33: Backlog | G33: [SGGU] PI 3/26 | H33: SGGU-5288 | K33: 0 | L33: 3 | M33: [SGGU] SP 26.3.2 | AF33: [Jornada Secretaria e Gestor de Unidades] Gestor de Unidades | AG33: Jornada Secretaria e Gestor de Unidades
A34: História | B34: [SGGU-5187] Plano de virada - Add acesso ao menu por perfil de acesso | C34: SGGU-6367 | D34: Backlog | G34: [SGGU] PI 3/26 | H34: SGGU-5187 | K34: 2 | L34: 2 | M34: [SGGU] SP 26.3.5 | AF34: [Jornada Secretaria e Gestor de Unidades] Gestor de Unidades | AG34: Jornada Secretaria e Gestor de Unidades
A35: Enabler | B35: [SGGU-5187] Plano de virada - Ajuste no Console para Inicialização e Conclusão do BPF de Mediadores Legados | C35: SGGU-6366 | D35: Backlog | G35: [SGGU] PI 3/26 | H35: SGGU-5187 | K35: 2 | L35: 2 | M35: [SGGU] SP 26.3.5 | AF35: [Jornada Secretaria e Gestor de Unidades] Gestor de Unidades | AG35: Jornada Secretaria e Gestor de Unidades
A36: Débito Técnico | B36: [SGGU-5187] Correção da Regra de Reaproveitamento de Documentos entre Semestres | C36: SGGU-6364 | D36: Em Andamento | G36: [SGGU] PI 3/26 | H36: SGGU-5187 | K36: 5 | L36: 5 | M36: [SGGU] SP 26.3.1 | AF36: [Jornada Secretaria e Gestor de Unidades] Gestor de Unidades | AG36: Jornada Secretaria e Gestor de Unidades
A37: Enabler | B37: [Estabilizar Deploy] Levantamento dos itens da solução mediador | C37: SGGU-6356 | D37: Backlog | G37: [SGGU] PI 3/26 | H37: ARTSG-190 | K37: 3 | L37: 3 | M37: [SGGU] SP 26.3.1 | AF37: [Jornada Secretaria e Gestor de Unidades] Gestor de Unidades | AG37: Jornada Secretaria e Gestor de Unidades
... A49: Enabler | B49: [ARTPT-669] Plano virada de ambiente do Épico para PRD | C49: SGGU-6318 | D49: Backlog | G49: [SGGU] PI 3/26 | H49: ARTPT-669 | K49: 1 | L49: 1 | M49: [SGGU] SP 26.3.1 | AF49: [Jornada Secretaria e Gestor de Unidades] Gestor de Unidades | AG49: Jornada Secretaria e Gestor de Unidades
A50: Sustentação | B50: Atendimento à Solicitações de Serviço | C50: SGGU-6317 | D50: Backlog | G50: [SGGU] PI 3/26 | K50: 3 | L50: 3 | M50: [SGGU] SP 26.3.6 | AF50: [Jornada Secretaria e Gestor de Unidades] Gestor de Unidades | AG50: Jornada Secretaria e Gestor de Unidades | AO50: Solicitação de Serviço
A51: Sustentação | B51: Atendimento à Solicitações de Serviço | C51: SGGU-6316 | D51: Backlog | G51: [SGGU] PI 3/26 | K51: 3 | L51: 3 | M51: [SGGU] SP 26.3.5 | AF51: [Jornada Secretaria e Gestor de Unidades] Gestor de Unidades | AG51: Jornada Secretaria e Gestor de Unidades | AO51: Solicitação de Serviço
...

Sheet Extração Jira - Itens
A1: Tipo de item | B1: Chave | C1: Sprint | D1: Projeto | E1: Status | F1: Versões corrigidas | G1: Story Points | H1: Resumo | I1: Story point estimate | J1: Σ de Tempo Gasto | K1: Tipo | L1: Categoria do status | M1: Pai | N1: Alteração de escopo (após a última PIP)? | O1: Resolução | P1: Criado | Q1: Ponto de compromisso | R1: Inicio do fluxo | S1: Fim do fluxo | T1: Início Homologação | U1: Fim Homologação | V1: Início Implantação | W1: Fim Implantação | X1: Ciclo de Ideação | Y1: Ciclo de Desenvolvimento | Z1: Ciclo Homologação | AA1: Ciclo de Implantação | AB1: Lead Time | AC1: Costumer Lead Time | AD1: Tipo Sustentação | AE1: Este item sofreu antecipação de Sprint? | AF1: Ambiente | AG1: Tempo total bloqueado | AH1: Tempo Gasto (horas) | AI1: Check Dias | AJ1: Tempo de Bloqueio (Dias) | AK1: Ideação | AL1: Check Ideação | AM1: Desenvolvimento | AN1: Check Desenvolvimento | AO1: Homologação | AP1: Check Homologação | AQ1: Implantação | AR1: Check Implantação | AS1: Lead Time | AT1: Check Lead time | AU1: Epico
A2: Incidente | B2: SGTB-2860 | C2: [SGTB] SP 26.3.6 | D2: [Jornada Secretaria e Gestor de Unidades] Thunderbolts | E2: Aceito | F2: [SGTB] PI 3/26 | H2: [INC0821305]Tenho um Erro/Problema com o Sistema Colaborar - Colaborar - Cursos extensão | J2: 900 | L2: Itens concluídos | O2: Abertura indevida | P2: 46289.504 | Q2: 46279 | R2: 46290 | AH2: =IF(J2="","",J2/3600) -> 0.25 | AI2: =IF(COUNTIF(AG2, "*dia*"), "VERDADEIRO", "FALSO") -> FALSO | AJ2: =IF(AI2="VERDADEIRO",LEFT(AG2,2),0) -> 0 | AK2: =IF(OR(A2="Solicitação de Serviço",A2="Incidente",P2="",Q2=""),"",IF((NETWORKDAYS.INTL(P2,Q2,1)-1)=0,1,NETWORKDAYS.INTL(P2,Q2,1)-1)) | AL2: =IF(X2="","",AK2=X2) | AM2: =IF(OR(A2="Solicitação de Serviço",A2="Incidente",R2="",S2=""),"",IF((NETWORKDAYS.INTL(R2,S2,1)-1)=0,1,NETWORKDAYS.INTL(R2,S2,1)-1-AJ2)) | AN2: =IF(Y2="","",AM2=Y2) | AO2: =IF(OR(A2="Solicitação de Serviço",A2="Incidente",T2="",U2=""),"",IF((NETWORKDAYS.INTL(T2,U2,1)-1)=0,1,NETWORKDAYS.INTL(T2,U2,1)-1)) | AP2: =IF(Z2="","",AO2=Z2) | AQ2: =IF(OR(A2="Solicitação de Serviço",A2="Incidente",V2="",W2=""),"",IF((NETWORKDAYS.INTL(V2,W2,1)-1)=0,1,IF((NETWORKDAYS.INTL(V2,W2,1)-1)<0,"",NETWORKDAYS.INTL(V2,W2,1)-1))) | AR2: =IF(AA2="","",AQ2=AA2) | AS2: =IF(OR(A2="Solicitação de Serviço",A2="Incidente",P2=""),"",IF(OR(A2="História",A2="Enabler",A2="Débito Técnico"),IF(W2="","",NETWORKDAYS.INTL(P2,W2,1)-1),IF(U2="","",NETWORKDAYS.INTL(P2,U2,1)-1))) | AT2: =IF(OR(A2="Solicitação de Serviço",A2="Incidente",A2="Sustentação"),"",IF(P2="","",IF(OR(A2="História",A2="Enabler",A2="Débito Técnico"),AS2=AC2,AS2=AB2))) | AU2: =IF(M2="","",M2)
A3: Incidente | B3: SGTB-2856 | C3: [SGTB] SP 26.4.1;[SGTB] SP 26.3.6 | D3: [Jornada Secretaria e Gestor de Unidades] Thunderbolts | E3: Aceito | F3: [SGTB] PI 3/26 | H3: [INC0819324]Tenho um Erro/Problema com o Sistema - AVA (LMS) - AVA (LMS) | J3: 1800 | L3: Itens concluídos | O3: Concluído | P3: 46289.433 | Q3: 46279 | R3: 46289 | S3: 46289 | AH3: =IF(J3="","",J3/3600) -> 0.5 | AI3: =IF(COUNTIF(AG3, "*dia*"), "VERDADEIRO", "FALSO") -> FALSO | AJ3: =IF(AI3="VERDADEIRO",LEFT(AG3,2),0) -> 0 | AK3: =IF(OR(A3="Solicitação de Serviço",A3="Incidente",P3="",Q3=""),"",IF((NETWORKDAYS.INTL(P3,Q3,1)-1)=0,1,NETWORKDAYS.INTL(P3,Q3,1)-1)) | AL3: =IF(X3="","",AK3=X3) | AM3: =IF(OR(A3="Solicitação de Serviço",A3="Incidente",R3="",S3=""),"",IF((NETWORKDAYS.INTL(R3,S3,1)-1)=0,1,NETWORKDAYS.INTL(R3,S3,1)-1-AJ3)) | AN3: =IF(Y3="","",AM3=Y3) | AO3: =IF(OR(A3="Solicitação de Serviço",A3="Incidente",T3="",U3=""),"",IF((NETWORKDAYS.INTL(T3,U3,1)-1)=0,1,NETWORKDAYS.INTL(T3,U3,1)-1)) | AP3: =IF(Z3="","",AO3=Z3) | AQ3: =IF(OR(A3="Solicitação de Serviço",A3="Incidente",V3="",W3=""),"",IF((NETWORKDAYS.INTL(V3,W3,1)-1)=0,1,IF((NETWORKDAYS.INTL(V3,W3,1)-1)<0,"",NETWORKDAYS.INTL(V3,W3,1)-1))) | AR3: =IF(AA3="","",AQ3=AA3) | AS3: =IF(OR(A3="Solicitação de Serviço",A3="Incidente",P3=""),"",IF(OR(A3="História",A3="Enabler",A3="Débito Técnico"),IF(W3="","",NETWORKDAYS.INTL(P3,W3,1)-1),IF(U3="","",NETWORKDAYS.INTL(P3,U3,1)-1))) | AT3: =IF(OR(A3="Solicitação de Serviço",A3="Incidente",A3="Sustentação"),"",IF(P3="","",IF(OR(A3="História",A3="Enabler",A3="Débito Técnico"),AS3=AC3,AS3=AB3))) | AU3: =IF(M3="","",M3)
A4: Incidente | B4: SGTB-2855 | C4: [SGTB] SP 26.4.1;[SGTB] SP 26.3.6 | D4: [Jornada Secretaria e Gestor de Unidades] Thunderbolts | E4: Aceito | F4: [SGTB] PI 3/26 | H4: [INC0817975]Tenho um Erro/Problema com o Sistema - AVA Presencial/Moodle - Acesso ao AVA/Disciplina | J4: 3600 | L4: Itens concluídos | O4: Concluído | P4: 46289.433 | Q4: 46279 | R4: 46289 | S4: 46289 | AH4: =IF(J4="","",J4/3600) -> 1 | AI4: =IF(COUNTIF(AG4, "*dia*"), "VERDADEIRO", "FALSO") -> FALSO | AJ4: =IF(AI4="VERDADEIRO",LEFT(AG4,2),0) -> 0 | AK4: =IF(OR(A4="Solicitação de Serviço",A4="Incidente",P4="",Q4=""),"",IF((NETWORKDAYS.INTL(P4,Q4,1)-1)=0,1,NETWORKDAYS.INTL(P4,Q4,1)-1)) | AL4: =IF(X4="","",AK4=X4) | AM4: =IF(OR(A4="Solicitação de Serviço",A4="Incidente",R4="",S4=""),"",IF((NETWORKDAYS.INTL(R4,S4,1)-1)=0,1,NETWORKDAYS.INTL(R4,S4,1)-1-AJ4)) | AN4: =IF(Y4="","",AM4=Y4) | AO4: =IF(OR(A4="Solicitação de Serviço",A4="Incidente",T4="",U4=""),"",IF((NETWORKDAYS.INTL(T4,U4,1)-1)=0,1,NETWORKDAYS.INTL(T4,U4,1)-1)) | AP4: =IF(Z4="","",AO4=Z4) | AQ4: =IF(OR(A4="Solicitação de Serviço",A4="Incidente",V4="",W4=""),"",IF((NETWORKDAYS.INTL(V4,W4,1)-1)=0,1,IF((NETWORKDAYS.INTL(V4,W4,1)-1)<0,"",NETWORKDAYS.INTL(V4,W4,1)-1))) | AR4: =IF(AA4="","",AQ4=AA4) | AS4: =IF(OR(A4="Solicitação de Serviço",A4="Incidente",P4=""),"",IF(OR(A4="História",A4="Enabler",A4="Débito Técnico"),IF(W4="","",NETWORKDAYS.INTL(P4,W4,1)-1),IF(U4="","",NETWORKDAYS.INTL(P4,U4,1)-1))) | AT4: =IF(OR(A4="Solicitação de Serviço",A4="Incidente",A4="Sustentação"),"",IF(P4="","",IF(OR(A4="História",A4="Enabler",A4="Débito Técnico"),AS4=AC4,AS4=AB4))) | AU4: =IF(M4="","",M4)
A5: Incidente | B5: SGTB-2853 | C5: [SGTB] SP 26.3.6 | D5: [Jornada Secretaria e Gestor de Unidades] Thunderbolts | E5: Aceito | F5: [SGTB] PI 3/26 | H5: [INC0822380]Tenho um Erro/Problema com o Sistema - Ajuste de Horário - Acadêmico | J5: 1800 | L5: Itens concluídos | O5: Abertura indevida | P5: 46289.403 | Q5: 46279 | R5: 46289 | AH5: =IF(J5="","",J5/3600) -> 0.5 | AI5: =IF(COUNTIF(AG5, "*dia*"), "VERDADEIRO", "FALSO") -> FALSO | AJ5: =IF(AI5="VERDADEIRO",LEFT(AG5,2),0) -> 0 | AK5: =IF(OR(A5="Solicitação de Serviço",A5="Incidente",P5="",Q5=""),"",IF((NETWORKDAYS.INTL(P5,Q5,1)-1)=0,1,NETWORKDAYS.INTL(P5,Q5,1)-1)) | AL5: =IF(X5="","",AK5=X5) | AM5: =IF(OR(A5="Solicitação de Serviço",A5="Incidente",R5="",S5=""),"",IF((NETWORKDAYS.INTL(R5,S5,1)-1)=0,1,NETWORKDAYS.INTL(R5,S5,1)-1-AJ5)) | AN5: =IF(Y5="","",AM5=Y5) | AO5: =IF(OR(A5="Solicitação de Serviço",A5="Incidente",T5="",U5=""),"",IF((NETWORKDAYS.INTL(T5,U5,1)-1)=0,1,NETWORKDAYS.INTL(T5,U5,1)-1)) | AP5: =IF(Z5="","",AO5=Z5) | AQ5: =IF(OR(A5="Solicitação de Serviço",A5="Incidente",V5="",W5=""),"",IF((NETWORKDAYS.INTL(V5,W5,1)-1)=0,1,IF((NETWORKDAYS.INTL(V5,W5,1)-1)<0,"",NETWORKDAYS.INTL(V5,W5,1)-1))) | AR5: =IF(AA5="","",AQ5=AA5) | AS5: =IF(OR(A5="Solicitação de Serviço",A5="Incidente",P5=""),"",IF(OR(A5="História",A5="Enabler",A5="Débito Técnico"),IF(W5="","",NETWORKDAYS.INTL(P5,W5,1)-1),IF(U5="","",NETWORKDAYS.INTL(P5,U5,1)-1))) | AT5: =IF(OR(A5="Solicitação de Serviço",A5="Incidente",A5="Sustentação"),"",IF(P5="","",IF(OR(A5="História",A5="Enabler",A5="Débito Técnico"),AS5=AC5,AS5=AB5))) | AU5: =IF(M5="","",M5)
A6: Solicitação de Serviço | B6: SGTB-2848 | C6: [SGTB] SP 26.4.1;[SGTB] SP 26.3.6 | D6: [Jornada Secretaria e Gestor de Unidades] Thunderbolts | E6: Aceito | F6: [SGTB] PI 3/26 | H6: [RITM0746664]Solicitar Serviço ao Sistema - Olimpo - Olimpo / Professores | J6: 600 | L6: Itens concluídos | O6: Concluído | P6: 46288.683 | Q6: 46279 | R6: 46290 | S6: 46290 | AH6: =IF(J6="","",J6/3600) -> 0.16666667 | AI6: =IF(COUNTIF(AG6, "*dia*"), "VERDADEIRO", "FALSO") -> FALSO | AJ6: =IF(AI6="VERDADEIRO",LEFT(AG6,2),0) -> 0 | AK6: =IF(OR(A6="Solicitação de Serviço",A6="Incidente",P6="",Q6=""),"",IF((NETWORKDAYS.INTL(P6,Q6,1)-1)=0,1,NETWORKDAYS.INTL(P6,Q6,1)-1)) | AL6: =IF(X6="","",AK6=X6) | AM6: =IF(OR(A6="Solicitação de Serviço",A6="Incidente",R6="",S6=""),"",IF((NETWORKDAYS.INTL(R6,S6,1)-1)=0,1,NETWORKDAYS.INTL(R6,S6,1)-1-AJ6)) | AN6: =IF(Y6="","",AM6=Y6) | AO6: =IF(OR(A6="Solicitação de Serviço",A6="Incidente",T6="",U6=""),"",IF((NETWORKDAYS.INTL(T6,U6,1)-1)=0,1,NETWORKDAYS.INTL(T6,U6,1)-1)) | AP6: =IF(Z6="","",AO6=Z6) | AQ6: =IF(OR(A6="Solicitação de Serviço",A6="Incidente",V6="",W6=""),"",IF((NETWORKDAYS.INTL(V6,W6,1)-1)=0,1,IF((NETWORKDAYS.INTL(V6,W6,1)-1)<0,"",NETWORKDAYS.INTL(V6,W6,1)-1))) | AR6: =IF(AA6="","",AQ6=AA6) | AS6: =IF(OR(A6="Solicitação de Serviço",A6="Incidente",P6=""),"",IF(OR(A6="História",A6="Enabler",A6="Débito Técnico"),IF(W6="","",NETWORKDAYS.INTL(P6,W6,1)-1),IF(U6="","",NETWORKDAYS.INTL(P6,U6,1)-1))) | AT6: =IF(OR(A6="Solicitação de Serviço",A6="Incidente",A6="Sustentação"),"",IF(P6="","",IF(OR(A6="História",A6="Enabler",A6="Débito Técnico"),AS6=AC6,AS6=AB6))) | AU6: =IF(M6="","",M6)
A7: Incidente | B7: SGTB-2847 | C7: [SGTB] SP 26.3.6 | D7: [Jornada Secretaria e Gestor de Unidades] Thunderbolts | E7: Aceito | F7: [SGTB] PI 3/26 | H7: [INC0822099]Tenho um Erro/Problema com o Sistema - Prisma - Usuários do Prisma | J7: 3600 | L7: Itens concluídos | O7: Abertura indevida | P7: 46288.681 | Q7: 46279 | R7: 46288 | AH7: =IF(J7="","",J7/3600) -> 1 | AI7: =IF(COUNTIF(AG7, "*dia*"), "VERDADEIRO", "FALSO") -> FALSO | AJ7: =IF(AI7="VERDADEIRO",LEFT(AG7,2),0) -> 0 | AK7: =IF(OR(A7="Solicitação de Serviço",A7="Incidente",P7="",Q7=""),"",IF((NETWORKDAYS.INTL(P7,Q7,1)-1)=0,1,NETWORKDAYS.INTL(P7,Q7,1)-1)) | AL7: =IF(X7="","",AK7=X7) | AM7: =IF(OR(A7="Solicitação de Serviço",A7="Incidente",R7="",S7=""),"",IF((NETWORKDAYS.INTL(R7,S7,1)-1)=0,1,NETWORKDAYS.INTL(R7,S7,1)-1-AJ7)) | AN7: =IF(Y7="","",AM7=Y7) | AO7: =IF(OR(A7="Solicitação de Serviço",A7="Incidente",T7="",U7=""),"",IF((NETWORKDAYS.INTL(T7,U7,1)-1)=0,1,NETWORKDAYS.INTL(T7,U7,1)-1)) | AP7: =IF(Z7="","",AO7=Z7) | AQ7: =IF(OR(A7="Solicitação de Serviço",A7="Incidente",V7="",W7=""),"",IF((NETWORKDAYS.INTL(V7,W7,1)-1)=0,1,IF((NETWORKDAYS.INTL(V7,W7,1)-1)<0,"",NETWORKDAYS.INTL(V7,W7,1)-1))) | AR7: =IF(AA7="","",AQ7=AA7) | AS7: =IF(OR(A7="Solicitação de Serviço",A7="Incidente",P7=""),"",IF(OR(A7="História",A7="Enabler",A7="Débito Técnico"),IF(W7="","",NETWORKDAYS.INTL(P7,W7,1)-1),IF(U7="","",NETWORKDAYS.INTL(P7,U7,1)-1))) | AT7: =IF(OR(A7="Solicitação de Serviço",A7="Incidente",A7="Sustentação"),"",IF(P7="","",IF(OR(A7="História",A7="Enabler",A7="Débito Técnico"),AS7=AC7,AS7=AB7))) | AU7: =IF(M7="","",M7)
A8: Incidente | B8: SGTB-2840 | C8: [SGTB] SP 26.4.1;[SGTB] SP 26.3.6 | D8: [Jornada Secretaria e Gestor de Unidades] Thunderbolts | E8: Aceito | F8: [SGTB] PI 3/26 | H8: [INC0819723]Tenho um Erro/Problema com o Sistema - Olimpo - Matrícula | J8: 10800 | L8: Itens concluídos | O8: Concluído | P8: 46288.458 | Q8: 46279 | R8: 46289 | S8: 46289 | AH8: =IF(J8="","",J8/3600) -> 3 | AI8: =IF(COUNTIF(AG8, "*dia*"), "VERDADEIRO", "FALSO") -> FALSO | AJ8: =IF(AI8="VERDADEIRO",LEFT(AG8,2),0) -> 0 | AK8: =IF(OR(A8="Solicitação de Serviço",A8="Incidente",P8="",Q8=""),"",IF((NETWORKDAYS.INTL(P8,Q8,1)-1)=0,1,NETWORKDAYS.INTL(P8,Q8,1)-1)) | AL8: =IF(X8="","",AK8=X8) | AM8: =IF(OR(A8="Solicitação de Serviço",A8="Incidente",R8="",S8=""),"",IF((NETWORKDAYS.INTL(R8,S8,1)-1)=0,1,NETWORKDAYS.INTL(R8,S8,1)-1-AJ8)) | AN8: =IF(Y8="","",AM8=Y8) | AO8: =IF(OR(A8="Solicitação de Serviço",A8="Incidente",T8="",U8=""),"",IF((NETWORKDAYS.INTL(T8,U8,1)-1)=0,1,NETWORKDAYS.INTL(T8,U8,1)-1)) | AP8: =IF(Z8="","",AO8=Z8) | AQ8: =IF(OR(A8="Solicitação de Serviço",A8="Incidente",V8="",W8=""),"",IF((NETWORKDAYS.INTL(V8,W8,1)-1)=0,1,IF((NETWORKDAYS.INTL(V8,W8,1)-1)<0,"",NETWORKDAYS.INTL(V8,W8,1)-1))) | AR8: =IF(AA8="","",AQ8=AA8) | AS8: =IF(OR(A8="Solicitação de Serviço",A8="Incidente",P8=""),"",IF(OR(A8="História",A8="Enabler",A8="Débito Técnico"),IF(W8="","",NETWORKDAYS.INTL(P8,W8,1)-1),IF(U8="","",NETWORKDAYS.INTL(P8,U8,1)-1))) | AT8: =IF(OR(A8="Solicitação de Serviço",A8="Incidente",A8="Sustentação"),"",IF(P8="","",IF(OR(A8="História",A8="Enabler",A8="Débito Técnico"),AS8=AC8,AS8=AB8))) | AU8: =IF(M8="","",M8)
A9: Incidente | B9: SGTB-2837 | C9: [SGTB] SP 26.3.6 | D9: [Jornada Secretaria e Gestor de Unidades] Thunderbolts | E9: Aceito | F9: [SGTB] PI 3/26 | H9: [INC0821361]Tenho um Erro/Problema com o Sistema - Extranet - Requerimento | J9: 900 | L9: Itens concluídos | O9: Abertura indevida | P9: 46288.45 | Q9: 46279 | R9: 46288 | AH9: =IF(J9="","",J9/3600) -> 0.25 | AI9: =IF(COUNTIF(AG9, "*dia*"), "VERDADEIRO", "FALSO") -> FALSO | AJ9: =IF(AI9="VERDADEIRO",LEFT(AG9,2),0) -> 0 | AK9: =IF(OR(A9="Solicitação de Serviço",A9="Incidente",P9="",Q9=""),"",IF((NETWORKDAYS.INTL(P9,Q9,1)-1)=0,1,NETWORKDAYS.INTL(P9,Q9,1)-1)) | AL9: =IF(X9="","",AK9=X9) | AM9: =IF(OR(A9="Solicitação de Serviço",A9="Incidente",R9="",S9=""),"",IF((NETWORKDAYS.INTL(R9,S9,1)-1)=0,1,NETWORKDAYS.INTL(R9,S9,1)-1-AJ9)) | AN9: =IF(Y9="","",AM9=Y9) | AO9: =IF(OR(A9="Solicitação de Serviço",A9="Incidente",T9="",U9=""),"",IF((NETWORKDAYS.INTL(T9,U9,1)-1)=0,1,NETWORKDAYS.INTL(T9,U9,1)-1)) | AP9: =IF(Z9="","",AO9=Z9) | AQ9: =IF(OR(A9="Solicitação de Serviço",A9="Incidente",V9="",W9=""),"",IF((NETWORKDAYS.INTL(V9,W9,1)-1)=0,1,IF((NETWORKDAYS.INTL(V9,W9,1)-1)<0,"",NETWORKDAYS.INTL(V9,W9,1)-1))) | AR9: =IF(AA9="","",AQ9=AA9) | AS9: =IF(OR(A9="Solicitação de Serviço",A9="Incidente",P9=""),"",IF(OR(A9="História",A9="Enabler",A9="Débito Técnico"),IF(W9="","",NETWORKDAYS.INTL(P9,W9,1)-1),IF(U9="","",NETWORKDAYS.INTL(P9,U9,1)-1))) | AT9: =IF(OR(A9="Solicitação de Serviço",A9="Incidente",A9="Sustentação"),"",IF(P9="","",IF(OR(A9="História",A9="Enabler",A9="Débito Técnico"),AS9=AC9,AS9=AB9))) | AU9: =IF(M9="","",M9)
A10: Incidente | B10: SGTB-2835 | C10: [SGTB] SP 26.3.6 | D10: [Jornada Secretaria e Gestor de Unidades] Thunderbolts | E10: Aceito | F10: [SGTB] PI 3/26 | H10: [INC0821364]Tenho um Erro/Problema com o Sistema - Extranet - (Extranet) Atendimento | J10: 900 | L10: Itens concluídos | O10: Abertura indevida | P10: 46288.444 | Q10: 46279 | R10: 46288 | AH10: =IF(J10="","",J10/3600) -> 0.25 | AI10: =IF(COUNTIF(AG10, "*dia*"), "VERDADEIRO", "FALSO") -> FALSO | AJ10: =IF(AI10="VERDADEIRO",LEFT(AG10,2),0) -> 0 | AK10: =IF(OR(A10="Solicitação de Serviço",A10="Incidente",P10="",Q10=""),"",IF((NETWORKDAYS.INTL(P10,Q10,1)-1)=0,1,NETWORKDAYS.INTL(P10,Q10,1)-1)) | AL10: =IF(X10="","",AK10=X10) | AM10: =IF(OR(A10="Solicitação de Serviço",A10="Incidente",R10="",S10=""),"",IF((NETWORKDAYS.INTL(R10,S10,1)-1)=0,1,NETWORKDAYS.INTL(R10,S10,1)-1-AJ10)) | AN10: =IF(Y10="","",AM10=Y10) | AO10: =IF(OR(A10="Solicitação de Serviço",A10="Incidente",T10="",U10=""),"",IF((NETWORKDAYS.INTL(T10,U10,1)-1)=0,1,NETWORKDAYS.INTL(T10,U10,1)-1)) | AP10: =IF(Z10="","",AO10=Z10) | AQ10: =IF(OR(A10="Solicitação de Serviço",A10="Incidente",V10="",W10=""),"",IF((NETWORKDAYS.INTL(V10,W10,1)-1)=0,1,IF((NETWORKDAYS.INTL(V10,W10,1)-1)<0,"",NETWORKDAYS.INTL(V10,W10,1)-1))) | AR10: =IF(AA10="","",AQ10=AA10) | AS10: =IF(OR(A10="Solicitação de Serviço",A10="Incidente",P10=""),"",IF(OR(A10="História",A10="Enabler",A10="Débito Técnico"),IF(W10="","",NETWORKDAYS.INTL(P10,W10,1)-1),IF(U10="","",NETWORKDAYS.INTL(P10,U10,1)-1))) | AT10: =IF(OR(A10="Solicitação de Serviço",A10="Incidente",A10="Sustentação"),"",IF(P10="","",IF(OR(A10="História",A10="Enabler",A10="Débito Técnico"),AS10=AC10,AS10=AB10))) | AU10: =IF(M10="","",M10)
A11: Incidente | B11: SGTB-2829 | C11: [SGTB] SP 26.4.1;[SGTB] SP 26.3.6 | D11: [Jornada Secretaria e Gestor de Unidades] Thunderbolts | E11: Aceito | F11: [SGTB] PI 3/26 | H11: [INC0821332]Tenho um Erro/Problema com o Sistema - Portal do Professor - Portal do Professor | J11: 3600 | L11: Itens concluídos | O11: Concluído | P11: 46287.653 | Q11: 46279 | R11: 46288 | S11: 46288 | AH11: =IF(J11="","",J11/3600) -> 1 | AI11: =IF(COUNTIF(AG11, "*dia*"), "VERDADEIRO", "FALSO") -> FALSO | AJ11: =IF(AI11="VERDADEIRO",LEFT(AG11,2),0) -> 0 | AK11: =IF(OR(A11="Solicitação de Serviço",A11="Incidente",P11="",Q11=""),"",IF((NETWORKDAYS.INTL(P11,Q11,1)-1)=0,1,NETWORKDAYS.INTL(P11,Q11,1)-1)) | AL11: =IF(X11="","",AK11=X11) | AM11: =IF(OR(A11="Solicitação de Serviço",A11="Incidente",R11="",S11=""),"",IF((NETWORKDAYS.INTL(R11,S11,1)-1)=0,1,NETWORKDAYS.INTL(R11,S11,1)-1-AJ11)) | AN11: =IF(Y11="","",AM11=Y11) | AO11: =IF(OR(A11="Solicitação de Serviço",A11="Incidente",T11="",U11=""),"",IF((NETWORKDAYS.INTL(T11,U11,1)-1)=0,1,NETWORKDAYS.INTL(T11,U11,1)-1)) | AP11: =IF(Z11="","",AO11=Z11) | AQ11: =IF(OR(A11="Solicitação de Serviço",A11="Incidente",V11="",W11=""),"",IF((NETWORKDAYS.INTL(V11,W11,1)-1)=0,1,IF((NETWORKDAYS.INTL(V11,W11,1)-1)<0,"",NETWORKDAYS.INTL(V11,W11,1)-1))) | AR11: =IF(AA11="","",AQ11=AA11) | AS11: =IF(OR(A11="Solicitação de Serviço",A11="Incidente",P11=""),"",IF(OR(A11="História",A11="Enabler",A11="Débito Técnico"),IF(W11="","",NETWORKDAYS.INTL(P11,W11,1)-1),IF(U11="","",NETWORKDAYS.INTL(P11,U11,1)-1))) | AT11: =IF(OR(A11="Solicitação de Serviço",A11="Incidente",A11="Sustentação"),"",IF(P11="","",IF(OR(A11="História",A11="Enabler",A11="Débito Técnico"),AS11=AC11,AS11=AB11))) | AU11: =IF(M11="","",M11)
A12: Solicitação de Serviço | B12: SGTB-2828 | C12: [SGTB] SP 26.4.1;[SGTB] SP 26.3.6 | D12: [Jornada Secretaria e Gestor de Unidades] Thunderbolts | E12: Aceito | F12: [SGTB] PI 3/26 | H12: [RITM0746021]Solicitar um serviço para o Sistema Colaborar - Colaborar - Extranet Colaborar | J12: 1800 | L12: Itens concluídos | O12: Concluído | P12: 46287.635 | Q12: 46279 | R12: 46288 | S12: 46288 | AH12: =IF(J12="","",J12/3600) -> 0.5 | AI12: =IF(COUNTIF(AG12, "*dia*"), "VERDADEIRO", "FALSO") -> FALSO | AJ12: =IF(AI12="VERDADEIRO",LEFT(AG12,2),0) -> 0 | AK12: =IF(OR(A12="Solicitação de Serviço",A12="Incidente",P12="",Q12=""),"",IF((NETWORKDAYS.INTL(P12,Q12,1)-1)=0,1,NETWORKDAYS.INTL(P12,Q12,1)-1)) | AL12: =IF(X12="","",AK12=X12) | AM12: =IF(OR(A12="Solicitação de Serviço",A12="Incidente",R12="",S12=""),"",IF((NETWORKDAYS.INTL(R12,S12,1)-1)=0,1,NETWORKDAYS.INTL(R12,S12,1)-1-AJ12)) | AN12: =IF(Y12="","",AM12=Y12) | AO12: =IF(OR(A12="Solicitação de Serviço",A12="Incidente",T12="",U12=""),"",IF((NETWORKDAYS.INTL(T12,U12,1)-1)=0,1,NETWORKDAYS.INTL(T12,U12,1)-1)) | AP12: =IF(Z12="","",AO12=Z12) | AQ12: =IF(OR(A12="Solicitação de Serviço",A12="Incidente",V12="",W12=""),"",IF((NETWORKDAYS.INTL(V12,W12,1)-1)=0,1,IF((NETWORKDAYS.INTL(V12,W12,1)-1)<0,"",NETWORKDAYS.INTL(V12,W12,1)-1))) | AR12: =IF(AA12="","",AQ12=AA12) | AS12: =IF(OR(A12="Solicitação de Serviço",A12="Incidente",P12=""),"",IF(OR(A12="História",A12="Enabler",A12="Débito Técnico"),IF(W12="","",NETWORKDAYS.INTL(P12,W12,1)-1),IF(U12="","",NETWORKDAYS.INTL(P12,U12,1)-1))) | AT12: =IF(OR(A12="Solicitação de Serviço",A12="Incidente",A12="Sustentação"),"",IF(P12="","",IF(OR(A12="História",A12="Enabler",A12="Débito Técnico"),AS12=AC12,AS12=AB12))) | AU12: =IF(M12="","",M12)
A13: Incidente | B13: SGTB-2824 | C13: [SGTB] SP 26.4.1;[SGTB] SP 26.3.6 | D13: [Jornada Secretaria e Gestor de Unidades] Thunderbolts | E13: Aceito | F13: [SGTB] PI 3/26 | H13: [INC0821219]Tenho um Erro/Problema com o Sistema Colaborar - Colaborar - GED (DGA) | J13: 900 | L13: Itens concluídos | O13: Concluído | P13: 46287.614 | Q13: 46279 | R13: 46289 | S13: 46289 | AH13: =IF(J13="","",J13/3600) -> 0.25 | AI13: =IF(COUNTIF(AG13, "*dia*"), "VERDADEIRO", "FALSO") -> FALSO | AJ13: =IF(AI13="VERDADEIRO",LEFT(AG13,2),0) -> 0 | AK13: =IF(OR(A13="Solicitação de Serviço",A13="Incidente",P13="",Q13=""),"",IF((NETWORKDAYS.INTL(P13,Q13,1)-1)=0,1,NETWORKDAYS.INTL(P13,Q13,1)-1)) | AL13: =IF(X13="","",AK13=X13) | AM13: =IF(OR(A13="Solicitação de Serviço",A13="Incidente",R13="",S13=""),"",IF((NETWORKDAYS.INTL(R13,S13,1)-1)=0,1,NETWORKDAYS.INTL(R13,S13,1)-1-AJ13)) | AN13: =IF(Y13="","",AM13=Y13) | AO13: =IF(OR(A13="Solicitação de Serviço",A13="Incidente",T13="",U13=""),"",IF((NETWORKDAYS.INTL(T13,U13,1)-1)=0,1,NETWORKDAYS.INTL(T13,U13,1)-1)) | AP13: =IF(Z13="","",AO13=Z13) | AQ13: =IF(OR(A13="Solicitação de Serviço",A13="Incidente",V13="",W13=""),"",IF((NETWORKDAYS.INTL(V13,W13,1)-1)=0,1,IF((NETWORKDAYS.INTL(V13,W13,1)-1)<0,"",NETWORKDAYS.INTL(V13,W13,1)-1))) | AR13: =IF(AA13="","",AQ13=AA13) | AS13: =IF(OR(A13="Solicitação de Serviço",A13="Incidente",P13=""),"",IF(OR(A13="História",A13="Enabler",A13="Débito Técnico"),IF(W13="","",NETWORKDAYS.INTL(P13,W13,1)-1),IF(U13="","",NETWORKDAYS.INTL(P13,U13,1)-1))) | AT13: =IF(OR(A13="Solicitação de Serviço",A13="Incidente",A13="Sustentação"),"",IF(P13="","",IF(OR(A13="História",A13="Enabler",A13="Débito Técnico"),AS13=AC13,AS13=AB13))) | AU13: =IF(M13="","",M13)
A14: Incidente | B14: SGTB-2819 | C14: [SGTB] SP 26.4.1;[SGTB] SP 26.3.6 | D14: [Jornada Secretaria e Gestor de Unidades] Thunderbolts | E14: Aceito | F14: [SGTB] PI 3/26 | H14: [INC0821235]Tenho um Erro/Problema com o Sistema - Portal Prisma - Prisma - Usuários do Prisma | J14: 25200 | L14: Itens concluídos | O14: Concluído | P14: 46287.509 | Q14: 46279 | R14: 46289 | S14: 46289 | AH14: =IF(J14="","",J14/3600) -> 7 | AI14: =IF(COUNTIF(AG14, "*dia*"), "VERDADEIRO", "FALSO") -> FALSO | AJ14: =IF(AI14="VERDADEIRO",LEFT(AG14,2),0) -> 0 | AK14: =IF(OR(A14="Solicitação de Serviço",A14="Incidente",P14="",Q14=""),"",IF((NETWORKDAYS.INTL(P14,Q14,1)-1)=0,1,NETWORKDAYS.INTL(P14,Q14,1)-1)) | AL14: =IF(X14="","",AK14=X14) | AM14: =IF(OR(A14="Solicitação de Serviço",A14="Incidente",R14="",S14=""),"",IF((NETWORKDAYS.INTL(R14,S14,1)-1)=0,1,NETWORKDAYS.INTL(R14,S14,1)-1-AJ14)) | AN14: =IF(Y14="","",AM14=Y14) | AO14: =IF(OR(A14="Solicitação de Serviço",A14="Incidente",T14="",U14=""),"",IF((NETWORKDAYS.INTL(T14,U14,1)-1)=0,1,NETWORKDAYS.INTL(T14,U14,1)-1)) | AP14: =IF(Z14="","",AO14=Z14) | AQ14: =IF(OR(A14="Solicitação de Serviço",A14="Incidente",V14="",W14=""),"",IF((NETWORKDAYS.INTL(V14,W14,1)-1)=0,1,IF((NETWORKDAYS.INTL(V14,W14,1)-1)<0,"",NETWORKDAYS.INTL(V14,W14,1)-1))) | AR14: =IF(AA14="","",AQ14=AA14) | AS14: =IF(OR(A14="Solicitação de Serviço",A14="Incidente",P14=""),"",IF(OR(A14="História",A14="Enabler",A14="Débito Técnico"),IF(W14="","",NETWORKDAYS.INTL(P14,W14,1)-1),IF(U14="","",NETWORKDAYS.INTL(P14,U14,1)-1))) | AT14: =IF(OR(A14="Solicitação de Serviço",A14="Incidente",A14="Sustentação"),"",IF(P14="","",IF(OR(A14="História",A14="Enabler",A14="Débito Técnico"),AS14=AC14,AS14=AB14))) | AU14: =IF(M14="","",M14)
A15: Incidente | B15: SGTB-2818 | C15: [SGTB] SP 26.3.6 | D15: [Jornada Secretaria e Gestor de Unidades] Thunderbolts | E15: Aceito | F15: [SGTB] PI 3/26 | H15: [INC0819611]Tenho um Erro/Problema com o Sistema Colaborar - Colaborar - Administração de usuários | J15: 600 | L15: Itens concluídos | O15: Abertura indevida | P15: 46287.496 | Q15: 46279 | R15: 46288 | AH15: =IF(J15="","",J15/3600) -> 0.16666667 | AI15: =IF(COUNTIF(AG15, "*dia*"), "VERDADEIRO", "FALSO") -> FALSO | AJ15: =IF(AI15="VERDADEIRO",LEFT(AG15,2),0) -> 0 | AK15: =IF(OR(A15="Solicitação de Serviço",A15="Incidente",P15="",Q15=""),"",IF((NETWORKDAYS.INTL(P15,Q15,1)-1)=0,1,NETWORKDAYS.INTL(P15,Q15,1)-1)) | AL15: =IF(X15="","",AK15=X15) | AM15: =IF(OR(A15="Solicitação de Serviço",A15="Incidente",R15="",S15=""),"",IF((NETWORKDAYS.INTL(R15,S15,1)-1)=0,1,NETWORKDAYS.INTL(R15,S15,1)-1-AJ15)) | AN15: =IF(Y15="","",AM15=Y15) | AO15: =IF(OR(A15="Solicitação de Serviço",A15="Incidente",T15="",U15=""),"",IF((NETWORKDAYS.INTL(T15,U15,1)-1)=0,1,NETWORKDAYS.INTL(T15,U15,1)-1)) | AP15: =IF(Z15="","",AO15=Z15) | AQ15: =IF(OR(A15="Solicitação de Serviço",A15="Incidente",V15="",W15=""),"",IF((NETWORKDAYS.INTL(V15,W15,1)-1)=0,1,IF((NETWORKDAYS.INTL(V15,W15,1)-1)<0,"",NETWORKDAYS.INTL(V15,W15,1)-1))) | AR15: =IF(AA15="","",AQ15=AA15) | AS15: =IF(OR(A15="Solicitação de Serviço",A15="Incidente",P15=""),"",IF(OR(A15="História",A15="Enabler",A15="Débito Técnico"),IF(W15="","",NETWORKDAYS.INTL(P15,W15,1)-1),IF(U15="","",NETWORKDAYS.INTL(P15,U15,1)-1))) | AT15: =IF(OR(A15="Solicitação de Serviço",A15="Incidente",A15="Sustentação"),"",IF(P15="","",IF(OR(A15="História",A15="Enabler",A15="Débito Técnico"),AS15=AC15,AS15=AB15))) | AU15: =IF(M15="","",M15)
A16: Incidente | B16: SGTB-2815 | C16: [SGTB] SP 26.4.1;[SGTB] SP 26.3.6 | D16: [Jornada Secretaria e Gestor de Unidades] Thunderbolts | E16: Aceito | F16: [SGTB] PI 3/26 | H16: [INC0818183]Tenho um Erro/Problema com o PTC - Dynamics Athenas - Ocorrências | J16: 600 | L16: Itens concluídos | O16: Concluído | P16: 46287.49 | Q16: 46279 | R16: 46287 | S16: 46287 | AH16: =IF(J16="","",J16/3600) -> 0.16666667 | AI16: =IF(COUNTIF(AG16, "*dia*"), "VERDADEIRO", "FALSO") -> FALSO | AJ16: =IF(AI16="VERDADEIRO",LEFT(AG16,2),0) -> 0 | AK16: =IF(OR(A16="Solicitação de Serviço",A16="Incidente",P16="",Q16=""),"",IF((NETWORKDAYS.INTL(P16,Q16,1)-1)=0,1,NETWORKDAYS.INTL(P16,Q16,1)-1)) | AL16: =IF(X16="","",AK16=X16) | AM16: =IF(OR(A16="Solicitação de Serviço",A16="Incidente",R16="",S16=""),"",IF((NETWORKDAYS.INTL(R16,S16,1)-1)=0,1,NETWORKDAYS.INTL(R16,S16,1)-1-AJ16)) | AN16: =IF(Y16="","",AM16=Y16) | AO16: =IF(OR(A16="Solicitação de Serviço",A16="Incidente",T16="",U16=""),"",IF((NETWORKDAYS.INTL(T16,U16,1)-1)=0,1,NETWORKDAYS.INTL(T16,U16,1)-1)) | AP16: =IF(Z16="","",AO16=Z16) | AQ16: =IF(OR(A16="Solicitação de Serviço",A16="Incidente",V16="",W16=""),"",IF((NETWORKDAYS.INTL(V16,W16,1)-1)=0,1,IF((NETWORKDAYS.INTL(V16,W16,1)-1)<0,"",NETWORKDAYS.INTL(V16,W16,1)-1))) | AR16: =IF(AA16="","",AQ16=AA16) | AS16: =IF(OR(A16="Solicitação de Serviço",A16="Incidente",P16=""),"",IF(OR(A16="História",A16="Enabler",A16="Débito Técnico"),IF(W16="","",NETWORKDAYS.INTL(P16,W16,1)-1),IF(U16="","",NETWORKDAYS.INTL(P16,U16,1)-1))) | AT16: =IF(OR(A16="Solicitação de Serviço",A16="Incidente",A16="Sustentação"),"",IF(P16="","",IF(OR(A16="História",A16="Enabler",A16="Débito Técnico"),AS16=AC16,AS16=AB16))) | AU16: =IF(M16="","",M16)
A17: Incidente | B17: SGTB-2814 | C17: [SGTB] SP 26.3.6 | D17: [Jornada Secretaria e Gestor de Unidades] Thunderbolts | E17: Aceito | F17: [SGTB] PI 3/26 | H17: [INC0821180]Tenho um Erro/Problema com o Sistema - Olimpo - Concurso | L17: Itens concluídos | O17: Abertura indevida | P17: 46287.48 | Q17: 46279 | R17: 46287 | AH17: =IF(J17="","",J17/3600) | AI17: =IF(COUNTIF(AG17, "*dia*"), "VERDADEIRO", "FALSO") -> FALSO | AJ17: =IF(AI17="VERDADEIRO",LEFT(AG17,2),0) -> 0 | AK17: =IF(OR(A17="Solicitação de Serviço",A17="Incidente",P17="",Q17=""),"",IF((NETWORKDAYS.INTL(P17,Q17,1)-1)=0,1,NETWORKDAYS.INTL(P17,Q17,1)-1)) | AL17: =IF(X17="","",AK17=X17) | AM17: =IF(OR(A17="Solicitação de Serviço",A17="Incidente",R17="",S17=""),"",IF((NETWORKDAYS.INTL(R17,S17,1)-1)=0,1,NETWORKDAYS.INTL(R17,S17,1)-1-AJ17)) | AN17: =IF(Y17="","",AM17=Y17) | AO17: =IF(OR(A17="Solicitação de Serviço",A17="Incidente",T17="",U17=""),"",IF((NETWORKDAYS.INTL(T17,U17,1)-1)=0,1,NETWORKDAYS.INTL(T17,U17,1)-1)) | AP17: =IF(Z17="","",AO17=Z17) | AQ17: =IF(OR(A17="Solicitação de Serviço",A17="Incidente",V17="",W17=""),"",IF((NETWORKDAYS.INTL(V17,W17,1)-1)=0,1,IF((NETWORKDAYS.INTL(V17,W17,1)-1)<0,"",NETWORKDAYS.INTL(V17,W17,1)-1))) | AR17: =IF(AA17="","",AQ17=AA17) | AS17: =IF(OR(A17="Solicitação de Serviço",A17="Incidente",P17=""),"",IF(OR(A17="História",A17="Enabler",A17="Débito Técnico"),IF(W17="","",NETWORKDAYS.INTL(P17,W17,1)-1),IF(U17="","",NETWORKDAYS.INTL(P17,U17,1)-1))) | AT17: =IF(OR(A17="Solicitação de Serviço",A17="Incidente",A17="Sustentação"),"",IF(P17="","",IF(OR(A17="História",A17="Enabler",A17="Débito Técnico"),AS17=AC17,AS17=AB17))) | AU17: =IF(M17="","",M17)
A18: Incidente | B18: SGTB-2812 | C18: [SGTB] SP 26.4.1;[SGTB] SP 26.3.6 | D18: [Jornada Secretaria e Gestor de Unidades] Thunderbolts | E18: Aceito | F18: [SGTB] PI 3/26 | H18: [INC0821189]Tenho um Erro/Problema com o Sistema - Extranet - Enturmacao | J18: 25200 | L18: Itens concluídos | O18: Concluído | P18: 46287.46 | Q18: 46279 | R18: 46287 | S18: 46288 | AH18: =IF(J18="","",J18/3600) -> 7 | AI18: =IF(COUNTIF(AG18, "*dia*"), "VERDADEIRO", "FALSO") -> FALSO | AJ18: =IF(AI18="VERDADEIRO",LEFT(AG18,2),0) -> 0 | AK18: =IF(OR(A18="Solicitação de Serviço",A18="Incidente",P18="",Q18=""),"",IF((NETWORKDAYS.INTL(P18,Q18,1)-1)=0,1,NETWORKDAYS.INTL(P18,Q18,1)-1)) | AL18: =IF(X18="","",AK18=X18) | AM18: =IF(OR(A18="Solicitação de Serviço",A18="Incidente",R18="",S18=""),"",IF((NETWORKDAYS.INTL(R18,S18,1)-1)=0,1,NETWORKDAYS.INTL(R18,S18,1)-1-AJ18)) | AN18: =IF(Y18="","",AM18=Y18) | AO18: =IF(OR(A18="Solicitação de Serviço",A18="Incidente",T18="",U18=""),"",IF((NETWORKDAYS.INTL(T18,U18,1)-1)=0,1,NETWORKDAYS.INTL(T18,U18,1)-1)) | AP18: =IF(Z18="","",AO18=Z18) | AQ18: =IF(OR(A18="Solicitação de Serviço",A18="Incidente",V18="",W18=""),"",IF((NETWORKDAYS.INTL(V18,W18,1)-1)=0,1,IF((NETWORKDAYS.INTL(V18,W18,1)-1)<0,"",NETWORKDAYS.INTL(V18,W18,1)-1))) | AR18: =IF(AA18="","",AQ18=AA18) | AS18: =IF(OR(A18="Solicitação de Serviço",A18="Incidente",P18=""),"",IF(OR(A18="História",A18="Enabler",A18="Débito Técnico"),IF(W18="","",NETWORKDAYS.INTL(P18,W18,1)-1),IF(U18="","",NETWORKDAYS.INTL(P18,U18,1)-1))) | AT18: =IF(OR(A18="Solicitação de Serviço",A18="Incidente",A18="Sustentação"),"",IF(P18="","",IF(OR(A18="História",A18="Enabler",A18="Débito Técnico"),AS18=AC18,AS18=AB18))) | AU18: =IF(M18="","",M18)
A19: Incidente | B19: SGTB-2797 | C19: [SGTB] SP 26.3.6 | D19: [Jornada Secretaria e Gestor de Unidades] Thunderbolts | E19: Aceito | F19: [SGTB] PI 3/26 | H19: [INC0821158]Tenho um Erro/Problema com o Sistema Colaborar - Administrativo [Secretaria] - Operações Acadêmicas - Secretaria - Atendimento EAD | J19: 600 | L19: Itens concluídos | O19: Abertura indevida | P19: 46287.388 | Q19: 46279 | R19: 46287 | AH19: =IF(J19="","",J19/3600) -> 0.16666667 | AI19: =IF(COUNTIF(AG19, "*dia*"), "VERDADEIRO", "FALSO") -> FALSO | AJ19: =IF(AI19="VERDADEIRO",LEFT(AG19,2),0) -> 0 | AK19: =IF(OR(A19="Solicitação de Serviço",A19="Incidente",P19="",Q19=""),"",IF((NETWORKDAYS.INTL(P19,Q19,1)-1)=0,1,NETWORKDAYS.INTL(P19,Q19,1)-1)) | AL19: =IF(X19="","",AK19=X19) | AM19: =IF(OR(A19="Solicitação de Serviço",A19="Incidente",R19="",S19=""),"",IF((NETWORKDAYS.INTL(R19,S19,1)-1)=0,1,NETWORKDAYS.INTL(R19,S19,1)-1-AJ19)) | AN19: =IF(Y19="","",AM19=Y19) | AO19: =IF(OR(A19="Solicitação de Serviço",A19="Incidente",T19="",U19=""),"",IF((NETWORKDAYS.INTL(T19,U19,1)-1)=0,1,NETWORKDAYS.INTL(T19,U19,1)-1)) | AP19: =IF(Z19="","",AO19=Z19) | AQ19: =IF(OR(A19="Solicitação de Serviço",A19="Incidente",V19="",W19=""),"",IF((NETWORKDAYS.INTL(V19,W19,1)-1)=0,1,IF((NETWORKDAYS.INTL(V19,W19,1)-1)<0,"",NETWORKDAYS.INTL(V19,W19,1)-1))) | AR19: =IF(AA19="","",AQ19=AA19) | AS19: =IF(OR(A19="Solicitação de Serviço",A19="Incidente",P19=""),"",IF(OR(A19="História",A19="Enabler",A19="Débito Técnico"),IF(W19="","",NETWORKDAYS.INTL(P19,W19,1)-1),IF(U19="","",NETWORKDAYS.INTL(P19,U19,1)-1))) | AT19: =IF(OR(A19="Solicitação de Serviço",A19="Incidente",A19="Sustentação"),"",IF(P19="","",IF(OR(A19="História",A19="Enabler",A19="Débito Técnico"),AS19=AC19,AS19=AB19))) | AU19: =IF(M19="","",M19)
A20: Incidente | B20: SGTB-2746 | C20: [SGTB] SP 26.3.6 | D20: [Jornada Secretaria e Gestor de Unidades] Thunderbolts | E20: Aceito | F20: [SGTB] PI 3/26 | H20: [INC0818151]Tenho um Erro/Problema com o Sistema - PDA:Portal do aluno - Graduação - Erro no Estudar no AVA | L20: Itens concluídos | O20: Abertura indevida | P20: 46286.522 | Q20: 46279 | R20: 46286 | AH20: =IF(J20="","",J20/3600) | AI20: =IF(COUNTIF(AG20, "*dia*"), "VERDADEIRO", "FALSO") -> FALSO | AJ20: =IF(AI20="VERDADEIRO",LEFT(AG20,2),0) -> 0 | AK20: =IF(OR(A20="Solicitação de Serviço",A20="Incidente",P20="",Q20=""),"",IF((NETWORKDAYS.INTL(P20,Q20,1)-1)=0,1,NETWORKDAYS.INTL(P20,Q20,1)-1)) | AL20: =IF(X20="","",AK20=X20) | AM20: =IF(OR(A20="Solicitação de Serviço",A20="Incidente",R20="",S20=""),"",IF((NETWORKDAYS.INTL(R20,S20,1)-1)=0,1,NETWORKDAYS.INTL(R20,S20,1)-1-AJ20)) | AN20: =IF(Y20="","",AM20=Y20) | AO20: =IF(OR(A20="Solicitação de Serviço",A20="Incidente",T20="",U20=""),"",IF((NETWORKDAYS.INTL(T20,U20,1)-1)=0,1,NETWORKDAYS.INTL(T20,U20,1)-1)) | AP20: =IF(Z20="","",AO20=Z20) | AQ20: =IF(OR(A20="Solicitação de Serviço",A20="Incidente",V20="",W20=""),"",IF((NETWORKDAYS.INTL(V20,W20,1)-1)=0,1,IF((NETWORKDAYS.INTL(V20,W20,1)-1)<0,"",NETWORKDAYS.INTL(V20,W20,1)-1))) | AR20: =IF(AA20="","",AQ20=AA20) | AS20: =IF(OR(A20="Solicitação de Serviço",A20="Incidente",P20=""),"",IF(OR(A20="História",A20="Enabler",A20="Débito Técnico"),IF(W20="","",NETWORKDAYS.INTL(P20,W20,1)-1),IF(U20="","",NETWORKDAYS.INTL(P20,U20,1)-1))) | AT20: =IF(OR(A20="Solicitação de Serviço",A20="Incidente",A20="Sustentação"),"",IF(P20="","",IF(OR(A20="História",A20="Enabler",A20="Débito Técnico"),AS20=AC20,AS20=AB20))) | AU20: =IF(M20="","",M20)
A21: Incidente | B21: SGTB-2745 | C21: [SGTB] SP 26.3.6 | D21: [Jornada Secretaria e Gestor de Unidades] Thunderbolts | E21: Aceito | F21: [SGTB] PI 3/26 | H21: [INC0808474]Tenho um Erro/Problema com o Sistema - AVA (LMS) - AVA (LMS) | J21: 1800 | L21: Itens concluídos | O21: Abertura indevida | P21: 46286.501 | Q21: 46279 | R21: 46286 | AH21: =IF(J21="","",J21/3600) -> 0.5 | AI21: =IF(COUNTIF(AG21, "*dia*"), "VERDADEIRO", "FALSO") -> FALSO | AJ21: =IF(AI21="VERDADEIRO",LEFT(AG21,2),0) -> 0 | AK21: =IF(OR(A21="Solicitação de Serviço",A21="Incidente",P21="",Q21=""),"",IF((NETWORKDAYS.INTL(P21,Q21,1)-1)=0,1,NETWORKDAYS.INTL(P21,Q21,1)-1)) | AL21: =IF(X21="","",AK21=X21) | AM21: =IF(OR(A21="Solicitação de Serviço",A21="Incidente",R21="",S21=""),"",IF((NETWORKDAYS.INTL(R21,S21,1)-1)=0,1,NETWORKDAYS.INTL(R21,S21,1)-1-AJ21)) | AN21: =IF(Y21="","",AM21=Y21) | AO21: =IF(OR(A21="Solicitação de Serviço",A21="Incidente",T21="",U21=""),"",IF((NETWORKDAYS.INTL(T21,U21,1)-1)=0,1,NETWORKDAYS.INTL(T21,U21,1)-1)) | AP21: =IF(Z21="","",AO21=Z21) | AQ21: =IF(OR(A21="Solicitação de Serviço",A21="Incidente",V21="",W21=""),"",IF((NETWORKDAYS.INTL(V21,W21,1)-1)=0,1,IF((NETWORKDAYS.INTL(V21,W21,1)-1)<0,"",NETWORKDAYS.INTL(V21,W21,1)-1))) | AR21: =IF(AA21="","",AQ21=AA21) | AS21: =IF(OR(A21="Solicitação de Serviço",A21="Incidente",P21=""),"",IF(OR(A21="História",A21="Enabler",A21="Débito Técnico"),IF(W21="","",NETWORKDAYS.INTL(P21,W21,1)-1),IF(U21="","",NETWORKDAYS.INTL(P21,U21,1)-1))) | AT21: =IF(OR(A21="Solicitação de Serviço",A21="Incidente",A21="Sustentação"),"",IF(P21="","",IF(OR(A21="História",A21="Enabler",A21="Débito Técnico"),AS21=AC21,AS21=AB21))) | AU21: =IF(M21="","",M21)
A22: Incidente | B22: SGTB-2743 | C22: [SGTB] SP 26.4.1;[SGTB] SP 26.3.6 | D22: [Jornada Secretaria e Gestor de Unidades] Thunderbolts | E22: Aceito | F22: [SGTB] PI 3/26 | H22: [INC0819805]Tenho um Erro/Problema com o Sistema - Olimpo - BD - Olimpo Banco de Dados | J22: 14400 | L22: Itens concluídos | O22: Concluído | P22: 46286.454 | Q22: 46279 | R22: 46286 | S22: 46288 | AH22: =IF(J22="","",J22/3600) -> 4 | AI22: =IF(COUNTIF(AG22, "*dia*"), "VERDADEIRO", "FALSO") -> FALSO | AJ22: =IF(AI22="VERDADEIRO",LEFT(AG22,2),0) -> 0 | AK22: =IF(OR(A22="Solicitação de Serviço",A22="Incidente",P22="",Q22=""),"",IF((NETWORKDAYS.INTL(P22,Q22,1)-1)=0,1,NETWORKDAYS.INTL(P22,Q22,1)-1)) | AL22: =IF(X22="","",AK22=X22) | AM22: =IF(OR(A22="Solicitação de Serviço",A22="Incidente",R22="",S22=""),"",IF((NETWORKDAYS.INTL(R22,S22,1)-1)=0,1,NETWORKDAYS.INTL(R22,S22,1)-1-AJ22)) | AN22: =IF(Y22="","",AM22=Y22) | AO22: =IF(OR(A22="Solicitação de Serviço",A22="Incidente",T22="",U22=""),"",IF((NETWORKDAYS.INTL(T22,U22,1)-1)=0,1,NETWORKDAYS.INTL(T22,U22,1)-1)) | AP22: =IF(Z22="","",AO22=Z22) | AQ22: =IF(OR(A22="Solicitação de Serviço",A22="Incidente",V22="",W22=""),"",IF((NETWORKDAYS.INTL(V22,W22,1)-1)=0,1,IF((NETWORKDAYS.INTL(V22,W22,1)-1)<0,"",NETWORKDAYS.INTL(V22,W22,1)-1))) | AR22: =IF(AA22="","",AQ22=AA22) | AS22: =IF(OR(A22="Solicitação de Serviço",A22="Incidente",P22=""),"",IF(OR(A22="História",A22="Enabler",A22="Débito Técnico"),IF(W22="","",NETWORKDAYS.INTL(P22,W22,1)-1),IF(U22="","",NETWORKDAYS.INTL(P22,U22,1)-1))) | AT22: =IF(OR(A22="Solicitação de Serviço",A22="Incidente",A22="Sustentação"),"",IF(P22="","",IF(OR(A22="História",A22="Enabler",A22="Débito Técnico"),AS22=AC22,AS22=AB22))) | AU22: =IF(M22="","",M22)
A23: Incidente | B23: SGTB-2742 | C23: [SGTB] SP 26.4.1;[SGTB] SP 26.3.6 | D23: [Jornada Secretaria e Gestor de Unidades] Thunderbolts | E23: Aceito | F23: [SGTB] PI 3/26 | H23: [INC0819839]Tenho um Erro/Problema com o Sistema - Olimpo - Desktop - Consulta | J23: 3600 | L23: Itens concluídos | O23: Concluído | P23: 46286.454 | Q23: 46279 | R23: 46286 | S23: 46286 | AH23: =IF(J23="","",J23/3600) -> 1 | AI23: =IF(COUNTIF(AG23, "*dia*"), "VERDADEIRO", "FALSO") -> FALSO | AJ23: =IF(AI23="VERDADEIRO",LEFT(AG23,2),0) -> 0 | AK23: =IF(OR(A23="Solicitação de Serviço",A23="Incidente",P23="",Q23=""),"",IF((NETWORKDAYS.INTL(P23,Q23,1)-1)=0,1,NETWORKDAYS.INTL(P23,Q23,1)-1)) | AL23: =IF(X23="","",AK23=X23) | AM23: =IF(OR(A23="Solicitação de Serviço",A23="Incidente",R23="",S23=""),"",IF((NETWORKDAYS.INTL(R23,S23,1)-1)=0,1,NETWORKDAYS.INTL(R23,S23,1)-1-AJ23)) | AN23: =IF(Y23="","",AM23=Y23) | AO23: =IF(OR(A23="Solicitação de Serviço",A23="Incidente",T23="",U23=""),"",IF((NETWORKDAYS.INTL(T23,U23,1)-1)=0,1,NETWORKDAYS.INTL(T23,U23,1)-1)) | AP23: =IF(Z23="","",AO23=Z23) | AQ23: =IF(OR(A23="Solicitação de Serviço",A23="Incidente",V23="",W23=""),"",IF((NETWORKDAYS.INTL(V23,W23,1)-1)=0,1,IF((NETWORKDAYS.INTL(V23,W23,1)-1)<0,"",NETWORKDAYS.INTL(V23,W23,1)-1))) | AR23: =IF(AA23="","",AQ23=AA23) | AS23: =IF(OR(A23="Solicitação de Serviço",A23="Incidente",P23=""),"",IF(OR(A23="História",A23="Enabler",A23="Débito Técnico"),IF(W23="","",NETWORKDAYS.INTL(P23,W23,1)-1),IF(U23="","",NETWORKDAYS.INTL(P23,U23,1)-1))) | AT23: =IF(OR(A23="Solicitação de Serviço",A23="Incidente",A23="Sustentação"),"",IF(P23="","",IF(OR(A23="História",A23="Enabler",A23="Débito Técnico"),AS23=AC23,AS23=AB23))) | AU23: =IF(M23="","",M23)
